Workbook
Name test_formulas: 'compare-with-submitted'!$A$1:$O$59
Name test_formulas: 'helper-calculations'!$A$1:$AC$110
Name test_formulas: large!$A$1:$Z$79
Name test_formulas: medium!$A$1:$Z$79
Name test_formulas: small!$A$1:$Z$81
Name test_formulas: 'table-4'!$A$1:$AC$124
Name test_formulas: 'table-5'!$A$1:$P$72

Sheet EXACT TABLE
A1: EVERYTHING IN ONE PLACE
A3: EXACT TABLE 4 | L3: EXACT TABLE 5
A4: ='table-4'!A57 -> Query | B4: ='table-4'!B57 -> Dataset | C4: ='table-4'!C57 -> Iterations | D4: ='table-4'!D57 -> Collections | E4: ='table-4'!E57 -> Non-Recursive SQL | F4: ='table-4'!F57 -> TyQL | G4: ='table-4'!G57 -> JDBC_RSQL | H4: ='table-4'!H57 -> Speedup Collections | ... J4: ='table-4'!J57 -> Speedup JDBC_RSQL | L4: MAX-MIN-AVG | M4: ='table-5'!P57 -> 25000X, 0.12X, 2624.185625X
A5: ='table-4'!A58 -> Ancestry | B5: ='table-4'!B58 -> 0.01MB | C5: ='table-4'!C58 -> 3 | D5: ='table-4'!D58 -> 0.001 | E5: ='table-4'!E58 -> 0.045 | F5: ='table-4'!F58 -> 0.007 | G5: ='table-4'!G58 -> 0.006 | H5: ='table-4'!H58 -> 0.19X* | ... J5: ='table-4'!J58 -> 0.79X*
A6: ='table-4'!A59 -> 0 | B6: ='table-4'!B59 -> 10MB | C6: ='table-4'!C59 -> 15 | D6: ='table-4'!D59 -> 3.440 | E6: ='table-4'!E59 -> 0.435 | F6: ='table-4'!F59 -> 0.219 | G6: ='table-4'!G59 -> 0.233 | H6: ='table-4'!H59 -> 15.69X | ... J6: ='table-4'!J59 -> 1.06X*
A7: ='table-4'!A60 -> 0 | B7: ='table-4'!B60 -> 100MB | C7: ='table-4'!C60 -> 189 | D7: ='table-4'!D60 -> TO | E7: ='table-4'!E60 -> TO | F7: ='table-4'!F60 -> 39.965 | G7: ='table-4'!G60 -> 39.820 | H7: ='table-4'!H60 -> >15.01X | ... J7: ='table-4'!J60 -> 1.00X*
A8: ='table-4'!A61 -> APT | B8: ='table-4'!B61 -> 0.01MB | C8: ='table-4'!C61 -> 3 | D8: ='table-4'!D61 -> 0.001 | E8: ='table-4'!E61 -> 0.051 | F8: ='table-4'!F61 -> 0.015 | G8: ='table-4'!G61 -> 0.014 | H8: ='table-4'!H61 -> 0.10X | ... J8: ='table-4'!J61 -> 0.95X*
A9: ='table-4'!A62 -> 0 | B9: ='table-4'!B62 -> 0.02MB | C9: ='table-4'!C62 -> 4 | D9: ='table-4'!D62 -> 3.496 | E9: ='table-4'!E62 -> 0.091 | F9: ='table-4'!F62 -> 0.019 | G9: ='table-4'!G62 -> 0.018 | H9: ='table-4'!H62 -> 183.62X | ... J9: ='table-4'!J62 -> 0.96X*
A10: ='table-4'!A63 -> 0 | B10: ='table-4'!B63 -> 0.04MB | C10: ='table-4'!C63 -> 9 | D10: ='table-4'!D63 -> 31.093 | E10: ='table-4'!E63 -> 0.212 | F10: ='table-4'!F63 -> 0.040 | G10: ='table-4'!G63 -> 0.039 | H10: ='table-4'!H63 -> 773.25X | ... J10: ='table-4'!J63 -> 0.97X* | L10: MAX-MIN-AVG | M10: ='table-5'!P63 -> 1255.23X, 1X, 39.169375X
A11: ='table-4'!A64 -> ASPS | B11: ='table-4'!B64 -> 0.01MB | C11: ='table-4'!C64 -> 3 | D11: ='table-4'!D64 -> 0.004 | E11: ='table-4'!E64 -> 0.041 | F11: ='table-4'!F64 -> 0.013 | G11: ='table-4'!G64 -> 0.010 | H11: ='table-4'!H64 -> 0.27X | ... J11: ='table-4'!J64 -> 0.76X*
A12: ='table-4'!A65 -> 0 | B12: ='table-4'!B65 -> 1MB | C12: ='table-4'!C65 -> 3 | D12: ='table-4'!D65 -> 19.846 | E12: ='table-4'!E65 -> 0.185 | F12: ='table-4'!F65 -> 0.049 | G12: ='table-4'!G65 -> 0.045 | H12: ='table-4'!H65 -> 408.17X | ... J12: ='table-4'!J65 -> 0.93X*
A13: ='table-4'!A66 -> 0 | B13: ='table-4'!B66 -> 5MB | C13: ='table-4'!C66 -> 4 | D13: ='table-4'!D66 -> TO | E13: ='table-4'!E66 -> 0.663 | F13: ='table-4'!F66 -> 0.174 | G13: ='table-4'!G66 -> 0.178 | H13: ='table-4'!H66 -> >3448.28X | ... J13: ='table-4'!J66 -> 1.03X*
A14: ='table-4'!A67 -> BOM | B14: ='table-4'!B67 -> 0.01MB | C14: ='table-4'!C67 -> 2 | D14: ='table-4'!D67 -> 0.002 | E14: ='table-4'!E67 -> 0.038 | F14: ='table-4'!F67 -> 0.009 | G14: ='table-4'!G67 -> 0.009 | H14: ='table-4'!H67 -> 0.21X* | ... J14: ='table-4'!J67 -> 0.99X*
A15: ='table-4'!A68 -> 0 | B15: ='table-4'!B68 -> 2MB | C15: ='table-4'!C68 -> 5 | D15: ='table-4'!D68 -> 136.253 | E15: ='table-4'!E68 -> 0.566 | F15: ='table-4'!F68 -> 0.088 | G15: ='table-4'!G68 -> 0.090 | H15: ='table-4'!H68 -> 1541.17X | ... J15: ='table-4'!J68 -> 1.02X*
A16: ='table-4'!A69 -> 0 | B16: ='table-4'!B69 -> 20MB | C16: ='table-4'!C69 -> 22 | D16: ='table-4'!D69 -> TO | E16: ='table-4'!E69 -> 13.982 | F16: ='table-4'!F69 -> 2.044 | G16: ='table-4'!G69 -> 2.052 | H16: ='table-4'!H69 -> >293.54X | ... J16: ='table-4'!J69 -> 1.00X* | L16: MAX-MIN-AVG | M16: ='table-5'!P69 -> 1X, 1X, 1X
A17: ='table-4'!A70 -> CBA | B17: ='table-4'!B70 -> 0.02MB | C17: ='table-4'!C70 -> 9 | D17: ='table-4'!D70 -> 0.006 | E17: ='table-4'!E70 -> 0.368 | F17: ='table-4'!F70 -> 0.031 | G17: ='table-4'!G70 -> 0.028 | H17: ='table-4'!H70 -> 0.19X | ... J17: ='table-4'!J70 -> 0.91X*
A18: ='table-4'!A71 -> 0 | B18: ='table-4'!B71 -> 0.1MB | C18: ='table-4'!C71 -> 1 | D18: ='table-4'!D71 -> TO | E18: ='table-4'!E71 -> 0.071 | F18: ='table-4'!F71 -> 0.024 | G18: ='table-4'!G71 -> 0.018 | H18: ='table-4'!H71 -> >25000.00X | ... J18: ='table-4'!J71 -> 0.76X*
A19: ='table-4'!A72 -> 0 | B19: ='table-4'!B72 -> 0.2MB | C19: ='table-4'!C72 -> 1 | D19: ='table-4'!D72 -> TO | E19: ='table-4'!E72 -> 0.062 | F19: ='table-4'!F72 -> 0.025 | G19: ='table-4'!G72 -> 0.020 | H19: ='table-4'!H72 -> >24000.00X | ... J19: ='table-4'!J72 -> 0.78X*
A20: ='table-4'!A73 -> CC | B20: ='table-4'!B73 -> 0.01MB | C20: ='table-4'!C73 -> 3 | D20: ='table-4'!D73 -> 0.002 | E20: ='table-4'!E73 -> 0.067 | F20: ='table-4'!F73 -> 0.010 | G20: ='table-4'!G73 -> 0.011 | H20: ='table-4'!H73 -> 0.24X* | ... J20: ='table-4'!J73 -> 1.08X*
A21: ='table-4'!A74 -> 0 | B21: ='table-4'!B74 -> 1MB | C21: ='table-4'!C74 -> 3 | D21: ='table-4'!D74 -> 14.768 | E21: ='table-4'!E74 -> 0.766 | F21: ='table-4'!F74 -> 0.303 | G21: ='table-4'!G74 -> 0.292 | H21: ='table-4'!H74 -> 48.82X | ... J21: ='table-4'!J74 -> 0.96X*
A22: ='table-4'!A75 -> 0 | B22: ='table-4'!B75 -> 1.5MB | C22: ='table-4'!C75 -> 3 | D22: ='table-4'!D75 -> 33.902 | E22: ='table-4'!E75 -> 0.918 | F22: ='table-4'!F75 -> 0.739 | G22: ='table-4'!G75 -> 0.695 | H22: ='table-4'!H75 -> 45.85X | ... J22: ='table-4'!J75 -> 0.94X*
A23: ='table-4'!A76 -> CSPA | B23: ='table-4'!B76 -> 0.01MB | C23: ='table-4'!C76 -> 5 | D23: ='table-4'!D76 -> 0.002 | E23: ='table-4'!E76 -> 0.155 | F23: ='table-4'!F76 -> 0.026 | G23: ='table-4'!G76 -> 0.021 | H23: ='table-4'!H76 -> 0.09X | ... J23: ='table-4'!J76 -> 0.80X*
A24: ='table-4'!A77 -> 0 | B24: ='table-4'!B77 -> 2MB | C24: ='table-4'!C77 -> 11 | D24: ='table-4'!D77 -> TO | E24: ='table-4'!E77 -> 5.713 | F24: ='table-4'!F77 -> 1.110 | G24: ='table-4'!G77 -> 1.059 | H24: ='table-4'!H77 -> >540.54X | ... J24: ='table-4'!J77 -> 0.95X*
A25: ='table-4'!A78 -> 0 | B25: ='table-4'!B78 -> 10MB | C25: ='table-4'!C78 -> 14 | D25: ='table-4'!D78 -> TO | E25: ='table-4'!E78 -> 280.456 | F25: ='table-4'!F78 -> 28.579 | G25: ='table-4'!G78 -> 28.562 | H25: ='table-4'!H78 -> >20.99X | ... J25: ='table-4'!J78 -> 1.00X*
A26: ='table-4'!A79 -> Data Flow | B26: ='table-4'!B79 -> 0.01MB | C26: ='table-4'!C79 -> 3 | D26: ='table-4'!D79 -> 0.002 | E26: ='table-4'!E79 -> 0.045 | F26: ='table-4'!F79 -> 0.007 | G26: ='table-4'!G79 -> 0.005 | H26: ='table-4'!H79 -> 0.29X* | ... J26: ='table-4'!J79 -> 0.65X*
A27: ='table-4'!A80 -> 0 | B27: ='table-4'!B80 -> 0.03MB | C27: ='table-4'!C80 -> 3 | D27: ='table-4'!D80 -> 18.281 | E27: ='table-4'!E80 -> 0.064 | F27: ='table-4'!F80 -> 0.008 | G27: ='table-4'!G80 -> 0.008 | H27: ='table-4'!H80 -> 2380.08X | ... J27: ='table-4'!J80 -> 1.06X*
A28: ='table-4'!A81 -> 0 | B28: ='table-4'!B81 -> 0.05MB | C28: ='table-4'!C81 -> 5 | D28: ='table-4'!D81 -> 210.906 | E28: ='table-4'!E81 -> 0.121 | F28: ='table-4'!F81 -> 0.011 | G28: ='table-4'!G81 -> 0.010 | H28: ='table-4'!H81 -> 18723.85X | ... J28: ='table-4'!J81 -> 0.91X*
... A52: ='table-4'!A105 -> 0 | B52: ='table-4'!B105 -> 15MB | C52: ='table-4'!C105 -> - | D52: ='table-4'!D105 -> TO | E52: ='table-4'!E105 -> 9.303 | F52: ='table-4'!F105 -> 1.344 | G52: ='table-4'!G105 -> 1.351 | H52: ='table-4'!H105 -> >446.43X | ... J52: ='table-4'!J105 -> 1.00X*

Sheet compare-with-submitted
B1: VS TYQL M: Submitted Paper Version (Bare metal) | G1: VS TYQL M: Docker artifact run by authors | L1: JUST RUN: M | Q1: DIFFERENCE VS. BARE METAL | V1: DIFFERENCE VS. AUTHORS DOCKER
B2: Speedup over Non-Recursive SQL | C2: Speedup over Collections | D2: Speedup over JDBC_RSQL | G2: Speedup over Non-Recursive SQL | H2: Speedup over Collections | I2: Speedup over JDBC_RSQL | L2: Speedup over Non-Recursive SQL | M2: Speedup over Collections | N2: Speedup over JDBC_RSQL | Q2: SS | R2: Coll | S2: JDBC | V2: SS | W2: Coll | X2: JDBC
A3: ancestry | B3: 2.6917155 | C3: 23.906749 | D3: 0.97950985 | G3: 1.98249 | H3: 15.690818 | I3: 1.0645303 | L3: =medium!Q3 -> 1.98249 | M3: =medium!R3 -> 15.690818 | N3: =medium!S3 -> 1.0645303 | Q3: =IF(AND(L3="DNF", B3="DNF"), "Both DNF",B3/ L3) -> 1.3577448 | R3: =IF(AND(M3="DNF", C3="DNF"), "Both DNF",C3/ M3) -> 1.523614 | S3: =IF(AND(N3="DNF", D3="DNF"), "Both DNF",D3/ N3) -> 0.92013341 | V3: =IF(AND(L3="DNF", G3="DNF"), "Both DNF",G3/ L3) -> 1 | W3: =IF(AND(M3="DNF", H3="DNF"), "Both DNF",H3/ M3) -> 1 | X3: =IF(AND(N3="DNF", I3="DNF"), "Both DNF",I3/ N3) -> 1
A4: andersens | B4: 5.1147135 | C4: 178.45725 | D4: 0.89757357 | G4: 4.7717077 | H4: 183.61995 | I4: 0.96112833 | L4: =medium!Q4 -> 4.7717077 | M4: =medium!R4 -> 183.61995 | N4: =medium!S4 -> 0.96112833 | Q4: =IF(AND(L4="DNF", B4="DNF"), "Both DNF",B4/ L4) -> 1.0718832 | R4: =IF(AND(M4="DNF", C4="DNF"), "Both DNF",C4/ M4) -> 0.97188379 | S4: =IF(AND(N4="DNF", D4="DNF"), "Both DNF",D4/ N4) -> 0.93387484 | V4: =IF(AND(L4="DNF", G4="DNF"), "Both DNF",G4/ L4) -> 1 | W4: =IF(AND(M4="DNF", H4="DNF"), "Both DNF",H4/ M4) -> 1 | X4: =IF(AND(N4="DNF", I4="DNF"), "Both DNF",I4/ N4) -> 1
A5: asps | B5: 3.4410959 | C5: 331.37775 | D5: 0.92481718 | G5: 3.8045535 | H5: 408.16507 | I5: 0.92731685 | L5: =medium!Q5 -> 3.8045535 | M5: =medium!R5 -> 408.16507 | N5: =medium!S5 -> 0.92731685 | Q5: =IF(AND(L5="DNF", B5="DNF"), "Both DNF",B5/ L5) -> 0.90446775 | R5: =IF(AND(M5="DNF", C5="DNF"), "Both DNF",C5/ M5) -> 0.8118719 | S5: =IF(AND(N5="DNF", D5="DNF"), "Both DNF",D5/ N5) -> 0.9973044 | V5: =IF(AND(L5="DNF", G5="DNF"), "Both DNF",G5/ L5) -> 1 | W5: =IF(AND(M5="DNF", H5="DNF"), "Both DNF",H5/ M5) -> 1 | X5: =IF(AND(N5="DNF", I5="DNF"), "Both DNF",I5/ N5) -> 1
A6: bom | B6: 6.7273081 | C6: 1725.1112 | D6: 0.90190202 | G6: 6.3965999 | H6: 1541.1704 | I6: 1.0152021 | L6: =medium!Q6 -> 6.3965999 | M6: =medium!R6 -> 1541.1704 | N6: =medium!S6 -> 1.0152021 | Q6: =IF(AND(L6="DNF", B6="DNF"), "Both DNF",B6/ L6) -> 1.0517006 | R6: =IF(AND(M6="DNF", C6="DNF"), "Both DNF",C6/ M6) -> 1.1193514 | S6: =IF(AND(N6="DNF", D6="DNF"), "Both DNF",D6/ N6) -> 0.88839655 | V6: =IF(AND(L6="DNF", G6="DNF"), "Both DNF",G6/ L6) -> 1 | W6: =IF(AND(M6="DNF", H6="DNF"), "Both DNF",H6/ M6) -> 1 | X6: =IF(AND(N6="DNF", I6="DNF"), "Both DNF",I6/ N6) -> 1
A7: cba | B7: 3.2105488 | C7: DNF | D7: 0.74722175 | G7: 2.9770416 | H7: DNF | I7: 0.76117324 | L7: =medium!Q7 -> 2.9770416 | M7: =medium!R7 -> DNF | N7: =medium!S7 -> 0.76117324 | Q7: =IF(AND(L7="DNF", B7="DNF"), "Both DNF",B7/ L7) -> 1.078436 | R7: =IF(AND(M7="DNF", C7="DNF"), "Both DNF",C7/ M7) -> Both DNF | S7: =IF(AND(N7="DNF", D7="DNF"), "Both DNF",D7/ N7) -> 0.98167106 | V7: =IF(AND(L7="DNF", G7="DNF"), "Both DNF",G7/ L7) -> 1 | W7: =IF(AND(M7="DNF", H7="DNF"), "Both DNF",H7/ M7) -> Both DNF | X7: =IF(AND(N7="DNF", I7="DNF"), "Both DNF",I7/ N7) -> 1
A8: cc | B8: 2.5104857 | C8: 51.666345 | D8: 1.0305373 | G8: 2.5325726 | H8: 48.818683 | I8: 0.963611 | L8: =medium!Q8 -> 2.5325726 | M8: =medium!R8 -> 48.818683 | N8: =medium!S8 -> 0.963611 | Q8: =IF(AND(L8="DNF", B8="DNF"), "Both DNF",B8/ L8) -> 0.99127886 | R8: =IF(AND(M8="DNF", C8="DNF"), "Both DNF",C8/ M8) -> 1.0583314 | S8: =IF(AND(N8="DNF", D8="DNF"), "Both DNF",D8/ N8) -> 1.0694536 | V8: =IF(AND(L8="DNF", G8="DNF"), "Both DNF",G8/ L8) -> 1 | W8: =IF(AND(M8="DNF", H8="DNF"), "Both DNF",H8/ M8) -> 1 | X8: =IF(AND(N8="DNF", I8="DNF"), "Both DNF",I8/ N8) -> 1
A9: cspa | B9: 5.6078175 | C9: DNF | D9: 0.98667774 | G9: 5.147048 | H9: DNF | I9: 0.95371694 | L9: =medium!Q9 -> 5.147048 | M9: =medium!R9 -> DNF | N9: =medium!S9 -> 0.95371694 | Q9: =IF(AND(L9="DNF", B9="DNF"), "Both DNF",B9/ L9) -> 1.0895211 | R9: =IF(AND(M9="DNF", C9="DNF"), "Both DNF",C9/ M9) -> Both DNF | S9: =IF(AND(N9="DNF", D9="DNF"), "Both DNF",D9/ N9) -> 1.0345604 | V9: =IF(AND(L9="DNF", G9="DNF"), "Both DNF",G9/ L9) -> 1 | W9: =IF(AND(M9="DNF", H9="DNF"), "Both DNF",H9/ M9) -> Both DNF | X9: =IF(AND(N9="DNF", I9="DNF"), "Both DNF",I9/ N9) -> 1
A10: dataflow | B10: 9.165342 | C10: 2592.2698 | D10: 1.1138234 | G10: 8.3276917 | H10: 2380.0753 | I10: 1.0634032 | L10: =medium!Q10 -> 8.3276917 | M10: =medium!R10 -> 2380.0753 | N10: =medium!S10 -> 1.0634032 | Q10: =IF(AND(L10="DNF", B10="DNF"), "Both DNF",B10/ L10) -> 1.1005861 | R10: =IF(AND(M10="DNF", C10="DNF"), "Both DNF",C10/ M10) -> 1.0891546 | S10: =IF(AND(N10="DNF", D10="DNF"), "Both DNF",D10/ N10) -> 1.047414 | V10: =IF(AND(L10="DNF", G10="DNF"), "Both DNF",G10/ L10) -> 1 | W10: =IF(AND(M10="DNF", H10="DNF"), "Both DNF",H10/ M10) -> 1 | X10: =IF(AND(N10="DNF", I10="DNF"), "Both DNF",I10/ N10) -> 1
A11: evenodd | B11: DNF | C11: DNF | D11: 1.0269684 | G11: DNF | H11: DNF | I11: 1.0066491 | L11: =medium!Q11 -> DNF | M11: =medium!R11 -> DNF | N11: =medium!S11 -> 1.0066491 | Q11: =IF(AND(L11="DNF", B11="DNF"), "Both DNF",B11/ L11) -> Both DNF | R11: =IF(AND(M11="DNF", C11="DNF"), "Both DNF",C11/ M11) -> Both DNF | S11: =IF(AND(N11="DNF", D11="DNF"), "Both DNF",D11/ N11) -> 1.020185 | V11: =IF(AND(L11="DNF", G11="DNF"), "Both DNF",G11/ L11) -> Both DNF | W11: =IF(AND(M11="DNF", H11="DNF"), "Both DNF",H11/ M11) -> Both DNF | X11: =IF(AND(N11="DNF", I11="DNF"), "Both DNF",I11/ N11) -> 1
A12: javapointsto | B12: 16.200211 | C12: DNF | D12: 1.0002257 | G12: 14.938213 | H12: DNF | I12: 0.95663155 | L12: =medium!Q12 -> 14.938213 | M12: =medium!R12 -> DNF | N12: =medium!S12 -> 0.95663155 | Q12: =IF(AND(L12="DNF", B12="DNF"), "Both DNF",B12/ L12) -> 1.0844812 | R12: =IF(AND(M12="DNF", C12="DNF"), "Both DNF",C12/ M12) -> Both DNF | S12: =IF(AND(N12="DNF", D12="DNF"), "Both DNF",D12/ N12) -> 1.0455705 | V12: =IF(AND(L12="DNF", G12="DNF"), "Both DNF",G12/ L12) -> 1 | W12: =IF(AND(M12="DNF", H12="DNF"), "Both DNF",H12/ M12) -> Both DNF | X12: =IF(AND(N12="DNF", I12="DNF"), "Both DNF",I12/ N12) -> 1
A13: orbits | B13: 5.3246648 | C13: DNF | D13: 0.98622141 | G13: 5.8934393 | H13: DNF | I13: 1.0383847 | L13: =medium!Q13 -> 5.8934393 | M13: =medium!R13 -> DNF | N13: =medium!S13 -> 1.0383847 | Q13: =IF(AND(L13="DNF", B13="DNF"), "Both DNF",B13/ L13) -> 0.90349022 | R13: =IF(AND(M13="DNF", C13="DNF"), "Both DNF",C13/ M13) -> Both DNF | S13: =IF(AND(N13="DNF", D13="DNF"), "Both DNF",D13/ N13) -> 0.94976498 | V13: =IF(AND(L13="DNF", G13="DNF"), "Both DNF",G13/ L13) -> 1 | W13: =IF(AND(M13="DNF", H13="DNF"), "Both DNF",H13/ M13) -> Both DNF | X13: =IF(AND(N13="DNF", I13="DNF"), "Both DNF",I13/ N13) -> 1
A14: party | B14: 6.9737904 | C14: DNF | D14: 0.93230647 | G14: 7.1658105 | H14: DNF | I14: 0.96221257 | L14: =medium!Q14 -> 7.1658105 | M14: =medium!R14 -> DNF | N14: =medium!S14 -> 0.96221257 | Q14: =IF(AND(L14="DNF", B14="DNF"), "Both DNF",B14/ L14) -> 0.97320329 | R14: =IF(AND(M14="DNF", C14="DNF"), "Both DNF",C14/ M14) -> Both DNF | S14: =IF(AND(N14="DNF", D14="DNF"), "Both DNF",D14/ N14) -> 0.96891944 | V14: =IF(AND(L14="DNF", G14="DNF"), "Both DNF",G14/ L14) -> 1 | W14: =IF(AND(M14="DNF", H14="DNF"), "Both DNF",H14/ M14) -> Both DNF | X14: =IF(AND(N14="DNF", I14="DNF"), "Both DNF",I14/ N14) -> 1
A15: pointstocount | B15: 16.491917 | C15: DNF | D15: 0.934318 | G15: 16.019783 | H15: DNF | I15: 0.96663686 | L15: =medium!Q15 -> 16.019783 | M15: =medium!R15 -> DNF | N15: =medium!S15 -> 0.96663686 | Q15: =IF(AND(L15="DNF", B15="DNF"), "Both DNF",B15/ L15) -> 1.0294719 | R15: =IF(AND(M15="DNF", C15="DNF"), "Both DNF",C15/ M15) -> Both DNF | S15: =IF(AND(N15="DNF", D15="DNF"), "Both DNF",D15/ N15) -> 0.96656566 | V15: =IF(AND(L15="DNF", G15="DNF"), "Both DNF",G15/ L15) -> 1 | W15: =IF(AND(M15="DNF", H15="DNF"), "Both DNF",H15/ M15) -> Both DNF | X15: =IF(AND(N15="DNF", I15="DNF"), "Both DNF",I15/ N15) -> 1
A16: sssp | B16: 6.0146968 | C16: 17.831875 | D16: 0.91482671 | G16: 5.4918167 | H16: 17.443499 | I16: 0.9343632 | L16: =medium!Q16 -> 5.4918167 | M16: =medium!R16 -> 17.443499 | N16: =medium!S16 -> 0.9343632 | Q16: =IF(AND(L16="DNF", B16="DNF"), "Both DNF",B16/ L16) -> 1.0952108 | R16: =IF(AND(M16="DNF", C16="DNF"), "Both DNF",C16/ M16) -> 1.0222648 | S16: =IF(AND(N16="DNF", D16="DNF"), "Both DNF",D16/ N16) -> 0.97909113 | V16: =IF(AND(L16="DNF", G16="DNF"), "Both DNF",G16/ L16) -> 1 | W16: =IF(AND(M16="DNF", H16="DNF"), "Both DNF",H16/ M16) -> 1 | X16: =IF(AND(N16="DNF", I16="DNF"), "Both DNF",I16/ N16) -> 1
A17: tc | B17: 3.5213203 | C17: 13.660014 | D17: 0.77045649 | G17: 3.5535822 | H17: 17.006759 | I17: 0.86342237 | L17: =medium!Q17 -> 3.5535822 | M17: =medium!R17 -> 17.006759 | N17: =medium!S17 -> 0.86342237 | Q17: =IF(AND(L17="DNF", B17="DNF"), "Both DNF",B17/ L17) -> 0.99092128 | R17: =IF(AND(M17="DNF", C17="DNF"), "Both DNF",C17/ M17) -> 0.80321088 | S17: =IF(AND(N17="DNF", D17="DNF"), "Both DNF",D17/ N17) -> 0.89232862 | V17: =IF(AND(L17="DNF", G17="DNF"), "Both DNF",G17/ L17) -> 1 | W17: =IF(AND(M17="DNF", H17="DNF"), "Both DNF",H17/ M17) -> 1 | X17: =IF(AND(N17="DNF", I17="DNF"), "Both DNF",I17/ N17) -> 1
A18: trustchain | B18: 22.078012 | C18: DNF | D18: 0.98670994 | G18: 20.514767 | H18: DNF | I18: 1.0183158 | L18: =medium!Q18 -> 20.514767 | M18: =medium!R18 -> DNF | N18: =medium!S18 -> 1.0183158 | Q18: =IF(AND(L18="DNF", B18="DNF"), "Both DNF",B18/ L18) -> 1.076201 | R18: =IF(AND(M18="DNF", C18="DNF"), "Both DNF",C18/ M18) -> Both DNF | S18: =IF(AND(N18="DNF", D18="DNF"), "Both DNF",D18/ N18) -> 0.9689626 | V18: =IF(AND(L18="DNF", G18="DNF"), "Both DNF",G18/ L18) -> 1 | W18: =IF(AND(M18="DNF", H18="DNF"), "Both DNF",H18/ M18) -> Both DNF | X18: =IF(AND(N18="DNF", I18="DNF"), "Both DNF",I18/ N18) -> 1
B21: VS TYQL L: Submitted Paper Version (Bare metal) | G21: VS TYQL L: Docker artifact run by authors | L21: JUST RUN: M
B22: Speedup over Non-Recursive SQL | C22: Speedup over Collections | D22: Speedup over JDBC_RSQL | G22: Speedup over Non-Recursive SQL | H22: Speedup over Collections | I22: Speedup over JDBC_RSQL | L22: Speedup over Non-Recursive SQL | M22: Speedup over Collections | N22: Speedup over JDBC_RSQL | Q22: SS | R22: Coll | S22: JDBC | V22: SS | W22: Coll | X22: JDBC
A23: ancestry | B23: DNF | C23: DNF | D23: 0.99888858 | G23: DNF | H23: DNF | I23: 0.99637978 | L23: =large!Q3 -> DNF | M23: =large!R3 -> DNF | N23: =large!S3 -> 0.99637978 | Q23: =IF(AND(L23="DNF", B23="DNF"), "Both DNF",B23/ L23) -> Both DNF | R23: =IF(AND(M23="DNF", C23="DNF"), "Both DNF",C23/ M23) -> Both DNF | S23: =IF(AND(N23="DNF", D23="DNF"), "Both DNF",D23/ N23) -> 1.0025179 | V23: =IF(AND(L23="DNF", G23="DNF"), "Both DNF",G23/ L23) -> Both DNF | W23: =IF(AND(M23="DNF", H23="DNF"), "Both DNF",H23/ M23) -> Both DNF | X23: =IF(AND(N23="DNF", I23="DNF"), "Both DNF",I23/ N23) -> 1
A24: andersens | B24: 5.9046005 | C24: 1019.2825 | D24: 0.90301413 | G24: 5.2713685 | H24: 773.2469 | I24: 0.97403696 | L24: =large!Q4 -> 5.2713685 | M24: =large!R4 -> 773.2469 | N24: =large!S4 -> 0.97403696 | Q24: =IF(AND(L24="DNF", B24="DNF"), "Both DNF",B24/ L24) -> 1.1201267 | R24: =IF(AND(M24="DNF", C24="DNF"), "Both DNF",C24/ M24) -> 1.3181851 | S24: =IF(AND(N24="DNF", D24="DNF"), "Both DNF",D24/ N24) -> 0.92708406 | V24: =IF(AND(L24="DNF", G24="DNF"), "Both DNF",G24/ L24) -> 1 | W24: =IF(AND(M24="DNF", H24="DNF"), "Both DNF",H24/ M24) -> 1 | X24: =IF(AND(N24="DNF", I24="DNF"), "Both DNF",I24/ N24) -> 1
A25: asps | B25: 3.4898416 | C25: DNF | D25: 0.97534099 | G25: 3.8140979 | H25: DNF | I25: 1.0253942 | L25: =large!Q5 -> 3.8140979 | M25: =large!R5 -> DNF | N25: =large!S5 -> 1.0253942 | Q25: =IF(AND(L25="DNF", B25="DNF"), "Both DNF",B25/ L25) -> 0.9149848 | R25: =IF(AND(M25="DNF", C25="DNF"), "Both DNF",C25/ M25) -> Both DNF | S25: =IF(AND(N25="DNF", D25="DNF"), "Both DNF",D25/ N25) -> 0.95118637 | V25: =IF(AND(L25="DNF", G25="DNF"), "Both DNF",G25/ L25) -> 1 | W25: =IF(AND(M25="DNF", H25="DNF"), "Both DNF",H25/ M25) -> Both DNF | X25: =IF(AND(N25="DNF", I25="DNF"), "Both DNF",I25/ N25) -> 1
A26: bom | B26: 7.651817 | C26: DNF | D26: 0.98945606 | G26: 6.8397004 | H26: DNF | I26: 1.0038988 | L26: =large!Q6 -> 6.8397004 | M26: =large!R6 -> DNF | N26: =large!S6 -> 1.0038988 | Q26: =IF(AND(L26="DNF", B26="DNF"), "Both DNF",B26/ L26) -> 1.1187357 | R26: =IF(AND(M26="DNF", C26="DNF"), "Both DNF",C26/ M26) -> Both DNF | S26: =IF(AND(N26="DNF", D26="DNF"), "Both DNF",D26/ N26) -> 0.98561336 | V26: =IF(AND(L26="DNF", G26="DNF"), "Both DNF",G26/ L26) -> 1 | W26: =IF(AND(M26="DNF", H26="DNF"), "Both DNF",H26/ M26) -> Both DNF | X26: =IF(AND(N26="DNF", I26="DNF"), "Both DNF",I26/ N26) -> 1
A27: cba | B27: 3.7135822 | C27: DNF | D27: 0.92525711 | G27: 2.4673241 | H27: DNF | I27: 0.77978454 | L27: =large!Q7 -> 2.4673241 | M27: =large!R7 -> DNF | N27: =large!S7 -> 0.77978454 | Q27: =IF(AND(L27="DNF", B27="DNF"), "Both DNF",B27/ L27) -> 1.5051051 | R27: =IF(AND(M27="DNF", C27="DNF"), "Both DNF",C27/ M27) -> Both DNF | S27: =IF(AND(N27="DNF", D27="DNF"), "Both DNF",D27/ N27) -> 1.1865548 | V27: =IF(AND(L27="DNF", G27="DNF"), "Both DNF",G27/ L27) -> 1 | W27: =IF(AND(M27="DNF", H27="DNF"), "Both DNF",H27/ M27) -> Both DNF | X27: =IF(AND(N27="DNF", I27="DNF"), "Both DNF",I27/ N27) -> 1
A28: cc | B28: 1.1055784 | C28: 51.288581 | D28: 0.97694119 | G28: 1.2417965 | H28: 45.851748 | I28: 0.93933718 | L28: =large!Q8 -> 1.2417965 | M28: =large!R8 -> 45.851748 | N28: =large!S8 -> 0.93933718 | Q28: =IF(AND(L28="DNF", B28="DNF"), "Both DNF",B28/ L28) -> 0.89030556 | R28: =IF(AND(M28="DNF", C28="DNF"), "Both DNF",C28/ M28) -> 1.1185742 | S28: =IF(AND(N28="DNF", D28="DNF"), "Both DNF",D28/ N28) -> 1.0400325 | V28: =IF(AND(L28="DNF", G28="DNF"), "Both DNF",G28/ L28) -> 1 | W28: =IF(AND(M28="DNF", H28="DNF"), "Both DNF",H28/ M28) -> 1 | X28: =IF(AND(N28="DNF", I28="DNF"), "Both DNF",I28/ N28) -> 1
A29: cspa | B29: 9.8081843 | C29: DNF | D29: 0.99368315 | G29: 9.8133639 | H29: DNF | I29: 0.99939512 | L29: =large!Q9 -> 9.8133639 | M29: =large!R9 -> DNF | N29: =large!S9 -> 0.99939512 | Q29: =IF(AND(L29="DNF", B29="DNF"), "Both DNF",B29/ L29) -> 0.9994722 | R29: =IF(AND(M29="DNF", C29="DNF"), "Both DNF",C29/ M29) -> Both DNF | S29: =IF(AND(N29="DNF", D29="DNF"), "Both DNF",D29/ N29) -> 0.99428458 | V29: =IF(AND(L29="DNF", G29="DNF"), "Both DNF",G29/ L29) -> 1 | W29: =IF(AND(M29="DNF", H29="DNF"), "Both DNF",H29/ M29) -> Both DNF | X29: =IF(AND(N29="DNF", I29="DNF"), "Both DNF",I29/ N29) -> 1
A30: dataflow | B30: 11.024188 | C30: 21897.752 | D30: 0.93245578 | G30: 10.709162 | H30: 18723.855 | I30: 0.91184304 | L30: =large!Q10 -> 10.709162 | M30: =large!R10 -> 18723.855 | N30: =large!S10 -> 0.91184304 | Q30: =IF(AND(L30="DNF", B30="DNF"), "Both DNF",B30/ L30) -> 1.0294165 | R30: =IF(AND(M30="DNF", C30="DNF"), "Both DNF",C30/ M30) -> 1.1695109 | S30: =IF(AND(N30="DNF", D30="DNF"), "Both DNF",D30/ N30) -> 1.0226056 | V30: =IF(AND(L30="DNF", G30="DNF"), "Both DNF",G30/ L30) -> 1 | W30: =IF(AND(M30="DNF", H30="DNF"), "Both DNF",H30/ M30) -> 1 | X30: =IF(AND(N30="DNF", I30="DNF"), "Both DNF",I30/ N30) -> 1
A31: evenodd | B31: DNF | C31: DNF | D31: 1.0419824 | G31: DNF | H31: DNF | I31: 0.98907127 | L31: =large!Q11 -> DNF | M31: =large!R11 -> DNF | N31: =large!S11 -> 0.98907127 | Q31: =IF(AND(L31="DNF", B31="DNF"), "Both DNF",B31/ L31) -> Both DNF | R31: =IF(AND(M31="DNF", C31="DNF"), "Both DNF",C31/ M31) -> Both DNF | S31: =IF(AND(N31="DNF", D31="DNF"), "Both DNF",D31/ N31) -> 1.0534958 | V31: =IF(AND(L31="DNF", G31="DNF"), "Both DNF",G31/ L31) -> Both DNF | W31: =IF(AND(M31="DNF", H31="DNF"), "Both DNF",H31/ M31) -> Both DNF | X31: =IF(AND(N31="DNF", I31="DNF"), "Both DNF",I31/ N31) -> 1
A32: javapointsto | B32: DNF | C32: DNF | D32: 0.9853863 | G32: DNF | H32: DNF | I32: 0.99774548 | L32: =large!Q12 -> DNF | M32: =large!R12 -> DNF | N32: =large!S12 -> 0.99774548 | Q32: =IF(AND(L32="DNF", B32="DNF"), "Both DNF",B32/ L32) -> Both DNF | R32: =IF(AND(M32="DNF", C32="DNF"), "Both DNF",C32/ M32) -> Both DNF | S32: =IF(AND(N32="DNF", D32="DNF"), "Both DNF",D32/ N32) -> 0.98761289 | V32: =IF(AND(L32="DNF", G32="DNF"), "Both DNF",G32/ L32) -> Both DNF | W32: =IF(AND(M32="DNF", H32="DNF"), "Both DNF",H32/ M32) -> Both DNF | X32: =IF(AND(N32="DNF", I32="DNF"), "Both DNF",I32/ N32) -> 1
A33: orbits | B33: 1.3858972 | C33: DNF | D33: 1.0046483 | G33: 1.0144915 | H33: DNF | I33: 1.009452 | L33: =large!Q13 -> 1.0144915 | M33: =large!R13 -> DNF | N33: =large!S13 -> 1.009452 | Q33: =IF(AND(L33="DNF", B33="DNF"), "Both DNF",B33/ L33) -> 1.3661003 | R33: =IF(AND(M33="DNF", C33="DNF"), "Both DNF",C33/ M33) -> Both DNF | S33: =IF(AND(N33="DNF", D33="DNF"), "Both DNF",D33/ N33) -> 0.99524129 | V33: =IF(AND(L33="DNF", G33="DNF"), "Both DNF",G33/ L33) -> 1 | W33: =IF(AND(M33="DNF", H33="DNF"), "Both DNF",H33/ M33) -> Both DNF | X33: =IF(AND(N33="DNF", I33="DNF"), "Both DNF",I33/ N33) -> 1
A34: party | B34: 3.5358011 | C34: DNF | D34: 1.020347 | G34: 3.8578671 | H34: DNF | I34: 0.99167232 | L34: =large!Q14 -> 3.8578671 | M34: =large!R14 -> DNF | N34: =large!S14 -> 0.99167232 | Q34: =IF(AND(L34="DNF", B34="DNF"), "Both DNF",B34/ L34) -> 0.91651708 | R34: =IF(AND(M34="DNF", C34="DNF"), "Both DNF",C34/ M34) -> Both DNF | S34: =IF(AND(N34="DNF", D34="DNF"), "Both DNF",D34/ N34) -> 1.0289155 | V34: =IF(AND(L34="DNF", G34="DNF"), "Both DNF",G34/ L34) -> 1 | W34: =IF(AND(M34="DNF", H34="DNF"), "Both DNF",H34/ M34) -> Both DNF | X34: =IF(AND(N34="DNF", I34="DNF"), "Both DNF",I34/ N34) -> 1
A35: pointstocount | B35: DNF | C35: DNF | D35: 0.97039064 | G35: DNF | H35: DNF | I35: 0.96530797 | L35: =large!Q15 -> DNF | M35: =large!R15 -> DNF | N35: =large!S15 -> 0.96530797 | Q35: =IF(AND(L35="DNF", B35="DNF"), "Both DNF",B35/ L35) -> Both DNF | R35: =IF(AND(M35="DNF", C35="DNF"), "Both DNF",C35/ M35) -> Both DNF | S35: =IF(AND(N35="DNF", D35="DNF"), "Both DNF",D35/ N35) -> 1.0052653 | V35: =IF(AND(L35="DNF", G35="DNF"), "Both DNF",G35/ L35) -> Both DNF | W35: =IF(AND(M35="DNF", H35="DNF"), "Both DNF",H35/ M35) -> Both DNF | X35: =IF(AND(N35="DNF", I35="DNF"), "Both DNF",I35/ N35) -> 1
A36: sssp | B36: 15.913491 | C36: 1762.8877 | D36: 1.0054916 | G36: 10.247392 | H36: 924.98827 | I36: 0.99303617 | L36: =large!Q16 -> 10.247392 | M36: =large!R16 -> 924.98827 | N36: =large!S16 -> 0.99303617 | Q36: =IF(AND(L36="DNF", B36="DNF"), "Both DNF",B36/ L36) -> 1.5529308 | R36: =IF(AND(M36="DNF", C36="DNF"), "Both DNF",C36/ M36) -> 1.9058487 | S36: =IF(AND(N36="DNF", D36="DNF"), "Both DNF",D36/ N36) -> 1.0125428 | V36: =IF(AND(L36="DNF", G36="DNF"), "Both DNF",G36/ L36) -> 1 | W36: =IF(AND(M36="DNF", H36="DNF"), "Both DNF",H36/ M36) -> 1 | X36: =IF(AND(N36="DNF", I36="DNF"), "Both DNF",I36/ N36) -> 1
A37: tc | B37: 4.4974961 | C37: 98.448347 | D37: 0.95398483 | G37: 3.5433878 | H37: 89.979303 | I37: 0.94651122 | L37: =large!Q17 -> 3.5433878 | M37: =large!R17 -> 89.979303 | N37: =large!S17 -> 0.94651122 | Q37: =IF(AND(L37="DNF", B37="DNF"), "Both DNF",B37/ L37) -> 1.2692644 | R37: =IF(AND(M37="DNF", C37="DNF"), "Both DNF",C37/ M37) -> 1.0941221 | S37: =IF(AND(N37="DNF", D37="DNF"), "Both DNF",D37/ N37) -> 1.007896 | V37: =IF(AND(L37="DNF", G37="DNF"), "Both DNF",G37/ L37) -> 1 | W37: =IF(AND(M37="DNF", H37="DNF"), "Both DNF",H37/ M37) -> 1 | X37: =IF(AND(N37="DNF", I37="DNF"), "Both DNF",I37/ N37) -> 1
A38: trustchain | B38: 9.6127214 | C38: DNF | D38: 0.97527109 | G38: 6.9205912 | H38: DNF | I38: 1.0047135 | L38: =large!Q18 -> 6.9205912 | M38: =large!R18 -> DNF | N38: =large!S18 -> 1.0047135 | Q38: =IF(AND(L38="DNF", B38="DNF"), "Both DNF",B38/ L38) -> 1.3890029 | R38: =IF(AND(M38="DNF", C38="DNF"), "Both DNF",C38/ M38) -> Both DNF | S38: =IF(AND(N38="DNF", D38="DNF"), "Both DNF",D38/ N38) -> 0.97069571 | V38: =IF(AND(L38="DNF", G38="DNF"), "Both DNF",G38/ L38) -> 1 | W38: =IF(AND(M38="DNF", H38="DNF"), "Both DNF",H38/ M38) -> Both DNF | X38: =IF(AND(N38="DNF", I38="DNF"), "Both DNF",I38/ N38) -> 1
B40: VS TYQL S: Submitted Paper Version (Bare metal) | G40: VS TYQL L: Docker artifact run by authors | L40: JUST RUN: S
B41: Speedup over Non-Recursive SQL | C41: Speedup over Collections | D41: Speedup over JDBC_RSQL | G41: Speedup over Non-Recursive SQL | L41: Speedup over Non-Recursive SQL | M41: Speedup over Collections | N41: Speedup over JDBC_RSQL | Q41: SS | R41: Coll | S41: JDBC | V41: SS | W41: Coll | X41: JDBC
A42: ancestry | B42: 6.5003972 | C42: 0.1840572 | D42: 0.71106992 | G42: 6.1550942 | H42: 0.19043036 | I42: 0.78963289 | L42: =small!Q3 -> 6.1550942 | M42: =small!R3 -> 0.19043036 | N42: =small!S3 -> 0.78963289 | Q42: =IF(AND(L42="DNF", B42="DNF"), "Both DNF",B42/ L42) -> 1.0561004 | R42: =IF(AND(M42="DNF", C42="DNF"), "Both DNF",C42/ M42) -> 0.96653288 | S42: =IF(AND(N42="DNF", D42="DNF"), "Both DNF",D42/ N42) -> 0.90050696 | V42: =IF(AND(L42="DNF", G42="DNF"), "Both DNF",G42/ L42) -> 1 | W42: =IF(AND(M42="DNF", H42="DNF"), "Both DNF",H42/ M42) -> 1 | X42: =IF(AND(N42="DNF", I42="DNF"), "Both DNF",I42/ N42) -> 1
A43: andersens | B43: 4.0844674 | C43: 0.10646048 | D43: 0.73512027 | G43: 3.4646417 | H43: 0.096982759 | I43: 0.95144127 | L43: =small!Q4 -> 3.4646417 | M43: =small!R4 -> 0.096982759 | N43: =small!S4 -> 0.95144127 | Q43: =IF(AND(L43="DNF", B43="DNF"), "Both DNF",B43/ L43) -> 1.1789004 | R43: =IF(AND(M43="DNF", C43="DNF"), "Both DNF",C43/ M43) -> 1.0977258 | S43: =IF(AND(N43="DNF", D43="DNF"), "Both DNF",D43/ N43) -> 0.77263862 | V43: =IF(AND(L43="DNF", G43="DNF"), "Both DNF",G43/ L43) -> 1 | W43: =IF(AND(M43="DNF", H43="DNF"), "Both DNF",H43/ M43) -> 1 | X43: =IF(AND(N43="DNF", I43="DNF"), "Both DNF",I43/ N43) -> 1
...

Sheet small
A1: >> INPUT SMALL CLEANED CSV HERE | Q1: VS TYQL | T1: VS JDBC_RSQL
A2: Backend | B2: Query | C2: Mode | D2: Threads | E2: Samples | F2: Score | G2: Score Error (99.9%) | H2: Unit | J2: Size | K2: Query | L2: Formal Name | M2: TyQL | N2: ScalaSQL | O2: Collections | P2: JDBC_RSQL | Q2: Speedup over Non-Recursive SQL | R2: Speedup over Collections | S2: Speedup over JDBC_RSQL | U2: Speedup over Non-Recursive SQL | V2: Speedup over Collections | W2: Speedup over TyQL
A3: Collections | B3: ancestry | C3: avgt | D3: 1 | E3: 5 | F3: 0.001385 | G3: 0.000217 | H3: s/op | J3: Large | K3: ancestry | L3: Ancestry | M3: {=INDEX($F$1:$F$100, MATCH(1, ($A$1:$A$100=M$2)*($B$1:$B$100=$K3), 0))} -> 0.007273 | N3: {=INDEX($F$1:$F$100, MATCH(1, (A$1:A$100=N$2)*(B$1:B$100=$K3), 0))} -> 0.044766 | O3: {=INDEX($F$1:$F$100, MATCH(1, (A$1:A$100=O$2)*(B$1:B$100=$K3), 0))} -> 0.001385 | P3: {=INDEX($F$1:$F$100, MATCH(1, (A$1:A$100=P$2)*(B$1:B$100=$K3), 0))} -> 0.005743 | Q3: =IF(ISNA($N3), "DNF", $N3/$M3) -> 6.1550942 | R3: =IF(ISNA(O3), "DNF", O3/$M3) -> 0.19043036 | S3: =IF(ISNA($P3), "DNF", $P3/$M3) -> 0.78963289 | U3: =IF(ISNA($N3), "DNF", $N3/$P3) -> 7.7948807 | V3: =IF(ISNA($O3), "DNF", $O3/$P3) -> 0.24116316 | W3: =IF(ISNA($M3), "DNF", $M3/$P3) -> 1.2664113
A4: Collections | B4: andersens | C4: avgt | D4: 1 | E4: 5 | F4: 0.00144 | G4: 0.000865 | H4: s/op | J4: Small | K4: andersens | L4: APT | M4: {=INDEX($F$1:$F$100, MATCH(1, (A$1:A$100=M$2)*(B$1:B$100=$K4), 0))} -> 0.014848 | N4: {=INDEX($F$1:$F$100, MATCH(1, (A$1:A$100=N$2)*(B$1:B$100=$K4), 0))} -> 0.051443 | O4: {=INDEX($F$1:$F$100, MATCH(1, (A$1:A$100=O$2)*(B$1:B$100=$K4), 0))} -> 0.00144 | P4: {=INDEX($F$1:$F$100, MATCH(1, (A$1:A$100=P$2)*(B$1:B$100=$K4), 0))} -> 0.014127 | Q4: =IF(ISNA($N4), "DNF", $N4/$M4) -> 3.4646417 | R4: =IF(ISNA(O4), "DNF", O4/$M4) -> 0.096982759 | S4: =IF(ISNA($P4), "DNF", $P4/$M4) -> 0.95144127 | U4: =IF(ISNA($N4), "DNF", $N4/$P4) -> 3.6414667 | V4: =IF(ISNA($O4), "DNF", $O4/$P4) -> 0.10193247 | W4: =IF(ISNA($M4), "DNF", $M4/$P4) -> 1.051037
A5: Collections | B5: asps | C5: avgt | D5: 1 | E5: 5 | F5: 0.003532 | G5: 0.001979 | H5: s/op | J5: Medium | K5: asps | L5: ASPS | M5: {=INDEX($F$1:$F$100, MATCH(1, (A$1:A$100=M$2)*(B$1:B$100=$K5), 0))} -> 0.013015 | N5: {=INDEX($F$1:$F$100, MATCH(1, (A$1:A$100=N$2)*(B$1:B$100=$K5), 0))} -> 0.041396 | O5: {=INDEX($F$1:$F$100, MATCH(1, (A$1:A$100=O$2)*(B$1:B$100=$K5), 0))} -> 0.003532 | P5: {=INDEX($F$1:$F$100, MATCH(1, (A$1:A$100=P$2)*(B$1:B$100=$K5), 0))} -> 0.009861 | Q5: =IF(ISNA($N5), "DNF", $N5/$M5) -> 3.1806377 | R5: =IF(ISNA(O5), "DNF", O5/$M5) -> 0.27137918 | S5: =IF(ISNA($P5), "DNF", $P5/$M5) -> 0.75766423 | U5: =IF(ISNA($N5), "DNF", $N5/$P5) -> 4.1979515 | V5: =IF(ISNA($O5), "DNF", $O5/$P5) -> 0.35817868 | W5: =IF(ISNA($M5), "DNF", $M5/$P5) -> 1.3198459
A6: Collections | B6: bom | C6: avgt | D6: 1 | E6: 5 | F6: 0.001808 | G6: 0.000933 | H6: s/op | J6: Medium | K6: bom | L6: BOM | M6: {=INDEX($F$1:$F$100, MATCH(1, (A$1:A$100=M$2)*(B$1:B$100=$K6), 0))} -> 0.008603 | N6: {=INDEX($F$1:$F$100, MATCH(1, (A$1:A$100=N$2)*(B$1:B$100=$K6), 0))} -> 0.037509 | O6: {=INDEX($F$1:$F$100, MATCH(1, (A$1:A$100=O$2)*(B$1:B$100=$K6), 0))} -> 0.001808 | P6: {=INDEX($F$1:$F$100, MATCH(1, (A$1:A$100=P$2)*(B$1:B$100=$K6), 0))} -> 0.008537 | Q6: =IF(ISNA($N6), "DNF", $N6/$M6) -> 4.3599907 | R6: =IF(ISNA(O6), "DNF", O6/$M6) -> 0.21015925 | S6: =IF(ISNA($P6), "DNF", $P6/$M6) -> 0.99232826 | U6: =IF(ISNA($N6), "DNF", $N6/$P6) -> 4.393698 | V6: =IF(ISNA($O6), "DNF", $O6/$P6) -> 0.211784 | W6: =IF(ISNA($M6), "DNF", $M6/$P6) -> 1.0077311
A7: Collections | B7: cba | C7: avgt | D7: 1 | E7: 5 | F7: 0.005959 | G7: 0.006517 | H7: s/op | J7: Small | K7: cba | L7: CBA | M7: {=INDEX($F$1:$F$100, MATCH(1, (A$1:A$100=M$2)*(B$1:B$100=$K7), 0))} -> 0.030929 | N7: {=INDEX($F$1:$F$100, MATCH(1, (A$1:A$100=N$2)*(B$1:B$100=$K7), 0))} -> 0.367689 | O7: {=INDEX($F$1:$F$100, MATCH(1, (A$1:A$100=O$2)*(B$1:B$100=$K7), 0))} -> 0.005959 | P7: {=INDEX($F$1:$F$100, MATCH(1, (A$1:A$100=P$2)*(B$1:B$100=$K7), 0))} -> 0.028028 | Q7: =IF(ISNA($N7), "DNF", $N7/$M7) -> 11.888163 | R7: =IF(ISNA(O7), "DNF", O7/$M7) -> 0.19266708 | S7: =IF(ISNA($P7), "DNF", $P7/$M7) -> 0.90620453 | U7: =IF(ISNA($N7), "DNF", $N7/$P7) -> 13.118631 | V7: =IF(ISNA($O7), "DNF", $O7/$P7) -> 0.21260882 | W7: =IF(ISNA($M7), "DNF", $M7/$P7) -> 1.1035036
A8: Collections | B8: cc | C8: avgt | D8: 1 | E8: 5 | F8: 0.002389 | G8: 0.000613 | H8: s/op | J8: Medium | K8: cc | L8: CC | M8: {=INDEX($F$1:$F$100, MATCH(1, (A$1:A$100=M$2)*(B$1:B$100=$K8), 0))} -> 0.009884 | N8: {=INDEX($F$1:$F$100, MATCH(1, (A$1:A$100=N$2)*(B$1:B$100=$K8), 0))} -> 0.067366 | O8: {=INDEX($F$1:$F$100, MATCH(1, (A$1:A$100=O$2)*(B$1:B$100=$K8), 0))} -> 0.002389 | P8: {=INDEX($F$1:$F$100, MATCH(1, (A$1:A$100=P$2)*(B$1:B$100=$K8), 0))} -> 0.010655 | Q8: =IF(ISNA($N8), "DNF", $N8/$M8) -> 6.8156617 | R8: =IF(ISNA(O8), "DNF", O8/$M8) -> 0.24170376 | S8: =IF(ISNA($P8), "DNF", $P8/$M8) -> 1.0780049 | U8: =IF(ISNA($N8), "DNF", $N8/$P8) -> 6.3224777 | V8: =IF(ISNA($O8), "DNF", $O8/$P8) -> 0.22421398 | W8: =IF(ISNA($M8), "DNF", $M8/$P8) -> 0.92763961
A9: Collections | B9: cspa | C9: avgt | D9: 1 | E9: 5 | F9: 0.002454 | G9: 0.002807 | H9: s/op | J9: Medium | K9: cspa | L9: CSPA | M9: {=INDEX($F$1:$F$100, MATCH(1, (A$1:A$100=M$2)*(B$1:B$100=$K9), 0))} -> 0.026327 | N9: {=INDEX($F$1:$F$100, MATCH(1, (A$1:A$100=N$2)*(B$1:B$100=$K9), 0))} -> 0.155402 | O9: {=INDEX($F$1:$F$100, MATCH(1, (A$1:A$100=O$2)*(B$1:B$100=$K9), 0))} -> 0.002454 | P9: {=INDEX($F$1:$F$100, MATCH(1, (A$1:A$100=P$2)*(B$1:B$100=$K9), 0))} -> 0.020952 | Q9: =IF(ISNA($N9), "DNF", $N9/$M9) -> 5.9027614 | R9: =IF(ISNA(O9), "DNF", O9/$M9) -> 0.093212292 | S9: =IF(ISNA($P9), "DNF", $P9/$M9) -> 0.79583697 | U9: =IF(ISNA($N9), "DNF", $N9/$P9) -> 7.4170485 | V9: =IF(ISNA($O9), "DNF", $O9/$P9) -> 0.11712486 | W9: =IF(ISNA($M9), "DNF", $M9/$P9) -> 1.2565388
A10: Collections | B10: dataflow | C10: avgt | D10: 1 | E10: 5 | F10: 0.002093 | G10: 0.001093 | H10: s/op | J10: Small | K10: dataflow | L10: Data Flow | M10: {=INDEX($F$1:$F$100, MATCH(1, (A$1:A$100=M$2)*(B$1:B$100=$K10), 0))} -> 0.007163 | N10: {=INDEX($F$1:$F$100, MATCH(1, (A$1:A$100=N$2)*(B$1:B$100=$K10), 0))} -> 0.045449 | O10: {=INDEX($F$1:$F$100, MATCH(1, (A$1:A$100=O$2)*(B$1:B$100=$K10), 0))} -> 0.002093 | P10: {=INDEX($F$1:$F$100, MATCH(1, (A$1:A$100=P$2)*(B$1:B$100=$K10), 0))} -> 0.004657 | Q10: =IF(ISNA($N10), "DNF", $N10/$M10) -> 6.3449672 | R10: =IF(ISNA(O10), "DNF", O10/$M10) -> 0.29219601 | S10: =IF(ISNA($P10), "DNF", $P10/$M10) -> 0.65014659 | U10: =IF(ISNA($N10), "DNF", $N10/$P10) -> 9.7592871 | V10: =IF(ISNA($O10), "DNF", $O10/$P10) -> 0.44943096 | W10: =IF(ISNA($M10), "DNF", $M10/$P10) -> 1.5381147
A11: Collections | B11: evenodd | C11: avgt | D11: 1 | E11: 5 | F11: 0.002481 | G11: 0.001979 | H11: s/op | J11: Medium | K11: evenodd | L11: Even-Odd | M11: {=INDEX($F$1:$F$100, MATCH(1, (A$1:A$100=M$2)*(B$1:B$100=$K11), 0))} -> 0.01121 | N11: {=INDEX($F$1:$F$100, MATCH(1, (A$1:A$100=N$2)*(B$1:B$100=$K11), 0))} -> 0.294978 | O11: {=INDEX($F$1:$F$100, MATCH(1, (A$1:A$100=O$2)*(B$1:B$100=$K11), 0))} -> 0.002481 | P11: {=INDEX($F$1:$F$100, MATCH(1, (A$1:A$100=P$2)*(B$1:B$100=$K11), 0))} -> 0.009539 | Q11: =IF(ISNA($N11), "DNF", $N11/$M11) -> 26.313827 | R11: =IF(ISNA(O11), "DNF", O11/$M11) -> 0.22132025 | S11: =IF(ISNA($P11), "DNF", $P11/$M11) -> 0.85093666 | U11: =IF(ISNA($N11), "DNF", $N11/$P11) -> 30.923367 | V11: =IF(ISNA($O11), "DNF", $O11/$P11) -> 0.26009016 | W11: =IF(ISNA($M11), "DNF", $M11/$P11) -> 1.1751756
A12: Collections | B12: javapointsto | C12: avgt | D12: 1 | E12: 5 | F12: 0.002125 | G12: 0.001068 | H12: s/op | J12: Small | K12: javapointsto | L12: JPT | M12: {=INDEX($F$1:$F$100, MATCH(1, (A$1:A$100=M$2)*(B$1:B$100=$K12), 0))} -> 0.017599 | N12: {=INDEX($F$1:$F$100, MATCH(1, (A$1:A$100=N$2)*(B$1:B$100=$K12), 0))} -> 0.071494 | O12: {=INDEX($F$1:$F$100, MATCH(1, (A$1:A$100=O$2)*(B$1:B$100=$K12), 0))} -> 0.002125 | P12: {=INDEX($F$1:$F$100, MATCH(1, (A$1:A$100=P$2)*(B$1:B$100=$K12), 0))} -> 0.012776 | Q12: =IF(ISNA($N12), "DNF", $N12/$M12) -> 4.0623899 | R12: =IF(ISNA(O12), "DNF", O12/$M12) -> 0.1207455 | S12: =IF(ISNA($P12), "DNF", $P12/$M12) -> 0.72595034 | U12: =IF(ISNA($N12), "DNF", $N12/$P12) -> 5.5959612 | V12: =IF(ISNA($O12), "DNF", $O12/$P12) -> 0.16632749 | W12: =IF(ISNA($M12), "DNF", $M12/$P12) -> 1.3775047
A13: Collections | B13: orbits | C13: avgt | D13: 1 | E13: 5 | F13: 0.00218 | G13: 0.001136 | H13: s/op | J13: Medium | K13: orbits | L13: Orbits | M13: {=INDEX($F$1:$F$100, MATCH(1, (A$1:A$100=M$2)*(B$1:B$100=$K13), 0))} -> 0.006883 | N13: {=INDEX($F$1:$F$100, MATCH(1, (A$1:A$100=N$2)*(B$1:B$100=$K13), 0))} -> 0.037434 | O13: {=INDEX($F$1:$F$100, MATCH(1, (A$1:A$100=O$2)*(B$1:B$100=$K13), 0))} -> 0.00218 | P13: {=INDEX($F$1:$F$100, MATCH(1, (A$1:A$100=P$2)*(B$1:B$100=$K13), 0))} -> 0.005871 | Q13: =IF(ISNA($N13), "DNF", $N13/$M13) -> 5.4386169 | R13: =IF(ISNA(O13), "DNF", O13/$M13) -> 0.31672236 | S13: =IF(ISNA($P13), "DNF", $P13/$M13) -> 0.85297109 | U13: =IF(ISNA($N13), "DNF", $N13/$P13) -> 6.3760858 | V13: =IF(ISNA($O13), "DNF", $O13/$P13) -> 0.37131664 | W13: =IF(ISNA($M13), "DNF", $M13/$P13) -> 1.1723727
A14: Collections | B14: party | C14: avgt | D14: 1 | E14: 5 | F14: 0.003474 | G14: 0.001945 | H14: s/op | J14: Medium | K14: party | L14: Party | M14: {=INDEX($F$1:$F$100, MATCH(1, (A$1:A$100=M$2)*(B$1:B$100=$K14), 0))} -> 0.008889 | N14: {=INDEX($F$1:$F$100, MATCH(1, (A$1:A$100=N$2)*(B$1:B$100=$K14), 0))} -> 0.074178 | O14: {=INDEX($F$1:$F$100, MATCH(1, (A$1:A$100=O$2)*(B$1:B$100=$K14), 0))} -> 0.003474 | P14: {=INDEX($F$1:$F$100, MATCH(1, (A$1:A$100=P$2)*(B$1:B$100=$K14), 0))} -> 0.005981 | Q14: =IF(ISNA($N14), "DNF", $N14/$M14) -> 8.3449207 | R14: =IF(ISNA(O14), "DNF", O14/$M14) -> 0.39082011 | S14: =IF(ISNA($P14), "DNF", $P14/$M14) -> 0.67285409 | U14: =IF(ISNA($N14), "DNF", $N14/$P14) -> 12.402274 | V14: =IF(ISNA($O14), "DNF", $O14/$P14) -> 0.58083932 | W14: =IF(ISNA($M14), "DNF", $M14/$P14) -> 1.4862063
A15: Collections | B15: pointstocount | C15: avgt | D15: 1 | E15: 5 | F15: 0.002103 | G15: 0.001082 | H15: s/op | J15: Small | K15: pointstocount | L15: PTC | M15: {=INDEX($F$1:$F$100, MATCH(1, (A$1:A$100=M$2)*(B$1:B$100=$K15), 0))} -> 0.014056 | N15: {=INDEX($F$1:$F$100, MATCH(1, (A$1:A$100=N$2)*(B$1:B$100=$K15), 0))} -> 0.078541 | O15: {=INDEX($F$1:$F$100, MATCH(1, (A$1:A$100=O$2)*(B$1:B$100=$K15), 0))} -> 0.002103 | P15: {=INDEX($F$1:$F$100, MATCH(1, (A$1:A$100=P$2)*(B$1:B$100=$K15), 0))} -> 0.014346 | Q15: =IF(ISNA($N15), "DNF", $N15/$M15) -> 5.5877205 | R15: =IF(ISNA(O15), "DNF", O15/$M15) -> 0.14961582 | S15: =IF(ISNA($P15), "DNF", $P15/$M15) -> 1.0206318 | U15: =IF(ISNA($N15), "DNF", $N15/$P15) -> 5.4747665 | V15: =IF(ISNA($O15), "DNF", $O15/$P15) -> 0.14659138 | W15: =IF(ISNA($M15), "DNF", $M15/$P15) -> 0.97978531
... A18: Collections | B18: trustchain | C18: avgt | D18: 1 | E18: 5 | F18: 0.002216 | G18: 0.001477 | H18: s/op | J18: Medium | K18: trustchain | L18: COT | M18: {=INDEX($F$1:$F$100, MATCH(1, (A$1:A$100=M$2)*(B$1:B$100=$K18), 0))} -> 0.012345 | N18: {=INDEX($F$1:$F$100, MATCH(1, (A$1:A$100=N$2)*(B$1:B$100=$K18), 0))} -> 0.14586 | O18: {=INDEX($F$1:$F$100, MATCH(1, (A$1:A$100=O$2)*(B$1:B$100=$K18), 0))} -> 0.002216 | P18: {=INDEX($F$1:$F$100, MATCH(1, (A$1:A$100=P$2)*(B$1:B$100=$K18), 0))} -> 0.007676 | Q18: =IF(ISNA($N18), "DNF", $N18/$M18) -> 11.81531 | R18: =IF(ISNA(O18), "DNF", O18/$M18) -> 0.17950587 | S18: =IF(ISNA($P18), "DNF", $P18/$M18) -> 0.6217902 | U18: =IF(ISNA($N18), "DNF", $N18/$P18) -> 19.002084 | V18: =IF(ISNA($O18), "DNF", $O18/$P18) -> 0.28869203 | W18: =IF(ISNA($M18), "DNF", $M18/$P18) -> 1.6082595
A19: JDBC_RSQL | B19: ancestry | C19: avgt | D19: 1 | E19: 5 | F19: 0.005743 | G19: 0.004029 | H19: s/op
A20: JDBC_RSQL | B20: andersens | C20: avgt | D20: 1 | E20: 5 | F20: 0.014127 | G20: 0.015078 | H20: s/op
A21: JDBC_RSQL | B21: asps | C21: avgt | D21: 1 | E21: 5 | F21: 0.009861 | G21: 0.01027 | H21: s/op
A22: JDBC_RSQL | B22: bom | C22: avgt | D22: 1 | E22: 5 | F22: 0.008537 | G22: 0.005846 | H22: s/op
A23: JDBC_RSQL | B23: cba | C23: avgt | D23: 1 | E23: 5 | F23: 0.028028 | G23: 0.005133 | H23: s/op
A24: JDBC_RSQL | B24: cc | C24: avgt | D24: 1 | E24: 5 | F24: 0.010655 | G24: 0.016179 | H24: s/op | J24: SCALASQL | P24: Margin of Error: | T24: TYQL Speedup exceeds error margin? | X24: JDBC_RSQL Speedup exceeds error margin?
A25: JDBC_RSQL | B25: cspa | C25: avgt | D25: 1 | E25: 5 | F25: 0.020952 | G25: 0.008621 | H25: s/op | J25: Query | K25: Large | L25: Medium | M25: Small | O25: Formal Name | P25: TyQL | Q25: ScalaSQL | R25: Collections | S25: JDBC_RSQL | T25: SCALASQL | U25: COLLECTIONS | V25: JDBC_RSQL | X25: SCALASQL | Y25: COLLECTIONS | Z25: TyQL
A26: JDBC_RSQL | B26: dataflow | C26: avgt | D26: 1 | E26: 5 | F26: 0.004657 | G26: 0.004197 | H26: s/op | J26: APT | K26: {=IFERROR(INDEX($Q$3:$Q$18, MATCH(1, ($J26=$L$3:$L$18) * (K$25=$J$3:$J$18), 0)), "")} | L26: {=IFERROR(INDEX($Q$3:$Q$18, MATCH(1, ($J26=$L$3:$L$18) * (L$25=$J$3:$J$18), 0)), "")} | M26: {=IFERROR(INDEX($Q$3:$Q$18, MATCH(1, ($J26=$L$3:$L$18) * (M$25=$J$3:$J$18), 0)), "")} -> 3.4646417 | O26: Ancestry | P26: {=INDEX($G$1:$G$100, MATCH(1, ($A$1:$A$100=P$25)*($B$1:$B$100=$K3), 0))} -> 0.010325 | Q26: {=INDEX($G$1:$G$100, MATCH(1, ($A$1:$A$100=Q$25)*($B$1:$B$100=$K3), 0))} -> 0.013146 | R26: {=INDEX($G$1:$G$100, MATCH(1, ($A$1:$A$100=R$25)*($B$1:$B$100=$K3), 0))} -> 0.000217 | S26: {=INDEX($G$1:$G$100, MATCH(1, ($A$1:$A$100=S$25)*($B$1:$B$100=$K3), 0))} -> 0.004029 | T26: =IF(ISNA(N3), TRUE, ABS($M3-N3) > MAX($P26, Q26)) -> TRUE | U26: =IF(ISNA(O3), TRUE, ABS($M3-O3) > MAX($P26, R26)) -> FALSE | V26: =IF(ISNA(P3), TRUE, ABS($M3-P3) > MAX($P26, S26)) -> FALSE | X26: =IF(ISNA(N3), TRUE, ABS($P3-N3) > MAX($S26, Q26)) -> TRUE | Y26: =IF(ISNA(O3), TRUE, ABS($P3-O3) > MAX($S26, R26)) -> TRUE | Z26: =IF(ISNA(M3), TRUE, ABS($P3-M3) > MAX($S26, P26)) -> FALSE
A27: JDBC_RSQL | B27: evenodd | C27: avgt | D27: 1 | E27: 5 | F27: 0.009539 | G27: 0.01026 | H27: s/op | J27: CBA | K27: {=IFERROR(INDEX($Q$3:$Q$18, MATCH(1, ($J27=$L$3:$L$18) * (K$25=$J$3:$J$18), 0)), "")} | L27: {=IFERROR(INDEX($Q$3:$Q$18, MATCH(1, ($J27=$L$3:$L$18) * (L$25=$J$3:$J$18), 0)), "")} | M27: {=IFERROR(INDEX($Q$3:$Q$18, MATCH(1, ($J27=$L$3:$L$18) * (M$25=$J$3:$J$18), 0)), "")} -> 11.888163 | O27: APT | P27: {=INDEX($G$1:$G$100, MATCH(1, ($A$1:$A$100=P$25)*($B$1:$B$100=$K4), 0))} -> 0.007322 | Q27: {=INDEX($G$1:$G$100, MATCH(1, ($A$1:$A$100=Q$25)*($B$1:$B$100=$K4), 0))} -> 0.022573 | R27: {=INDEX($G$1:$G$100, MATCH(1, ($A$1:$A$100=R$25)*($B$1:$B$100=$K4), 0))} -> 0.000865 | S27: {=INDEX($G$1:$G$100, MATCH(1, ($A$1:$A$100=S$25)*($B$1:$B$100=$K4), 0))} -> 0.015078 | T27: =IF(ISNA(N4), TRUE, ABS($M4-N4) > MAX($P27, Q27)) -> TRUE | U27: =IF(ISNA(O4), TRUE, ABS($M4-O4) > MAX($P27, R27)) -> TRUE | V27: =IF(ISNA(P4), TRUE, ABS($M4-P4) > MAX($P27, S27)) -> FALSE | X27: =IF(ISNA(N4), TRUE, ABS($P4-N4) > MAX($S27, Q27)) -> TRUE | Y27: =IF(ISNA(O4), TRUE, ABS($P4-O4) > MAX($S27, R27)) -> FALSE | Z27: =IF(ISNA(M4), TRUE, ABS($P4-M4) > MAX($S27, P27)) -> FALSE
A28: JDBC_RSQL | B28: javapointsto | C28: avgt | D28: 1 | E28: 5 | F28: 0.012776 | G28: 0.009462 | H28: s/op | J28: Data Flow | K28: {=IFERROR(INDEX($Q$3:$Q$18, MATCH(1, ($J28=$L$3:$L$18) * (K$25=$J$3:$J$18), 0)), "")} | L28: {=IFERROR(INDEX($Q$3:$Q$18, MATCH(1, ($J28=$L$3:$L$18) * (L$25=$J$3:$J$18), 0)), "")} | M28: {=IFERROR(INDEX($Q$3:$Q$18, MATCH(1, ($J28=$L$3:$L$18) * (M$25=$J$3:$J$18), 0)), "")} -> 6.3449672 | O28: ASPS | P28: {=INDEX($G$1:$G$100, MATCH(1, ($A$1:$A$100=P$25)*($B$1:$B$100=$K5), 0))} -> 0.008142 | Q28: {=INDEX($G$1:$G$100, MATCH(1, ($A$1:$A$100=Q$25)*($B$1:$B$100=$K5), 0))} -> 0.014372 | R28: {=INDEX($G$1:$G$100, MATCH(1, ($A$1:$A$100=R$25)*($B$1:$B$100=$K5), 0))} -> 0.001979 | S28: {=INDEX($G$1:$G$100, MATCH(1, ($A$1:$A$100=S$25)*($B$1:$B$100=$K5), 0))} -> 0.01027 | T28: =IF(ISNA(N5), TRUE, ABS($M5-N5) > MAX($P28, Q28)) -> TRUE | U28: =IF(ISNA(O5), TRUE, ABS($M5-O5) > MAX($P28, R28)) -> TRUE | V28: =IF(ISNA(P5), TRUE, ABS($M5-P5) > MAX($P28, S28)) -> FALSE | X28: =IF(ISNA(N5), TRUE, ABS($P5-N5) > MAX($S28, Q28)) -> TRUE | Y28: =IF(ISNA(O5), TRUE, ABS($P5-O5) > MAX($S28, R28)) -> FALSE | Z28: =IF(ISNA(M5), TRUE, ABS($P5-M5) > MAX($S28, P28)) -> FALSE
A29: JDBC_RSQL | B29: orbits | C29: avgt | D29: 1 | E29: 5 | F29: 0.005871 | G29: 0.005045 | H29: s/op | J29: JPT | K29: {=IFERROR(INDEX($Q$3:$Q$18, MATCH(1, ($J29=$L$3:$L$18) * (K$25=$J$3:$J$18), 0)), "")} | L29: {=IFERROR(INDEX($Q$3:$Q$18, MATCH(1, ($J29=$L$3:$L$18) * (L$25=$J$3:$J$18), 0)), "")} | M29: {=IFERROR(INDEX($Q$3:$Q$18, MATCH(1, ($J29=$L$3:$L$18) * (M$25=$J$3:$J$18), 0)), "")} -> 4.0623899 | O29: BOM | P29: {=INDEX($G$1:$G$100, MATCH(1, ($A$1:$A$100=P$25)*($B$1:$B$100=$K6), 0))} -> 0.008166 | Q29: {=INDEX($G$1:$G$100, MATCH(1, ($A$1:$A$100=Q$25)*($B$1:$B$100=$K6), 0))} -> 0.004934 | R29: {=INDEX($G$1:$G$100, MATCH(1, ($A$1:$A$100=R$25)*($B$1:$B$100=$K6), 0))} -> 0.000933 | S29: {=INDEX($G$1:$G$100, MATCH(1, ($A$1:$A$100=S$25)*($B$1:$B$100=$K6), 0))} -> 0.005846 | T29: =IF(ISNA(N6), TRUE, ABS($M6-N6) > MAX($P29, Q29)) -> TRUE | U29: =IF(ISNA(O6), TRUE, ABS($M6-O6) > MAX($P29, R29)) -> FALSE | V29: =IF(ISNA(P6), TRUE, ABS($M6-P6) > MAX($P29, S29)) -> FALSE | X29: =IF(ISNA(N6), TRUE, ABS($P6-N6) > MAX($S29, Q29)) -> TRUE | Y29: =IF(ISNA(O6), TRUE, ABS($P6-O6) > MAX($S29, R29)) -> TRUE | Z29: =IF(ISNA(M6), TRUE, ABS($P6-M6) > MAX($S29, P29)) -> FALSE
A30: JDBC_RSQL | B30: party | C30: avgt | D30: 1 | E30: 5 | F30: 0.005981 | G30: 0.004444 | H30: s/op | J30: PTC | K30: {=IFERROR(INDEX($Q$3:$Q$18, MATCH(1, ($J30=$L$3:$L$18) * (K$25=$J$3:$J$18), 0)), "")} | L30: {=IFERROR(INDEX($Q$3:$Q$18, MATCH(1, ($J30=$L$3:$L$18) * (L$25=$J$3:$J$18), 0)), "")} | M30: {=IFERROR(INDEX($Q$3:$Q$18, MATCH(1, ($J30=$L$3:$L$18) * (M$25=$J$3:$J$18), 0)), "")} -> 5.5877205 | O30: CBA | P30: {=INDEX($G$1:$G$100, MATCH(1, ($A$1:$A$100=P$25)*($B$1:$B$100=$K7), 0))} -> 0.010462 | Q30: {=INDEX($G$1:$G$100, MATCH(1, ($A$1:$A$100=Q$25)*($B$1:$B$100=$K7), 0))} -> 0.024418 | R30: {=INDEX($G$1:$G$100, MATCH(1, ($A$1:$A$100=R$25)*($B$1:$B$100=$K7), 0))} -> 0.006517 | S30: {=INDEX($G$1:$G$100, MATCH(1, ($A$1:$A$100=S$25)*($B$1:$B$100=$K7), 0))} -> 0.005133 | T30: =IF(ISNA(N7), TRUE, ABS($M7-N7) > MAX($P30, Q30)) -> TRUE | U30: =IF(ISNA(O7), TRUE, ABS($M7-O7) > MAX($P30, R30)) -> TRUE | V30: =IF(ISNA(P7), TRUE, ABS($M7-P7) > MAX($P30, S30)) -> FALSE | X30: =IF(ISNA(N7), TRUE, ABS($P7-N7) > MAX($S30, Q30)) -> TRUE | Y30: =IF(ISNA(O7), TRUE, ABS($P7-O7) > MAX($S30, R30)) -> TRUE | Z30: =IF(ISNA(M7), TRUE, ABS($P7-M7) > MAX($S30, P30)) -> FALSE
A31: JDBC_RSQL | B31: pointstocount | C31: avgt | D31: 1 | E31: 5 | F31: 0.014346 | G31: 0.00488 | H31: s/op | J31: ASPS | K31: {=IFERROR(INDEX($Q$3:$Q$18, MATCH(1, ($J31=$L$3:$L$18) * (K$25=$J$3:$J$18), 0)), "")} | L31: {=IFERROR(INDEX($Q$3:$Q$18, MATCH(1, ($J31=$L$3:$L$18) * (L$25=$J$3:$J$18), 0)), "")} -> 3.1806377 | M31: {=IFERROR(INDEX($Q$3:$Q$18, MATCH(1, ($J31=$L$3:$L$18) * (M$25=$J$3:$J$18), 0)), "")} | O31: CC | P31: {=INDEX($G$1:$G$100, MATCH(1, ($A$1:$A$100=P$25)*($B$1:$B$100=$K8), 0))} -> 0.009457 | Q31: {=INDEX($G$1:$G$100, MATCH(1, ($A$1:$A$100=Q$25)*($B$1:$B$100=$K8), 0))} -> 0.026911 | R31: {=INDEX($G$1:$G$100, MATCH(1, ($A$1:$A$100=R$25)*($B$1:$B$100=$K8), 0))} -> 0.000613 | S31: {=INDEX($G$1:$G$100, MATCH(1, ($A$1:$A$100=S$25)*($B$1:$B$100=$K8), 0))} -> 0.016179 | T31: =IF(ISNA(N8), TRUE, ABS($M8-N8) > MAX($P31, Q31)) -> TRUE | U31: =IF(ISNA(O8), TRUE, ABS($M8-O8) > MAX($P31, R31)) -> FALSE | V31: =IF(ISNA(P8), TRUE, ABS($M8-P8) > MAX($P31, S31)) -> FALSE | X31: =IF(ISNA(N8), TRUE, ABS($P8-N8) > MAX($S31, Q31)) -> TRUE | Y31: =IF(ISNA(O8), TRUE, ABS($P8-O8) > MAX($S31, R31)) -> FALSE | Z31: =IF(ISNA(M8), TRUE, ABS($P8-M8) > MAX($S31, P31)) -> FALSE
A32: JDBC_RSQL | B32: sssp | C32: avgt | D32: 1 | E32: 5 | F32: 0.008465 | G32: 0.00937 | H32: s/op | J32: BOM | K32: {=IFERROR(INDEX($Q$3:$Q$18, MATCH(1, ($J32=$L$3:$L$18) * (K$25=$J$3:$J$18), 0)), "")} | L32: {=IFERROR(INDEX($Q$3:$Q$18, MATCH(1, ($J32=$L$3:$L$18) * (L$25=$J$3:$J$18), 0)), "")} -> 4.3599907 | M32: {=IFERROR(INDEX($Q$3:$Q$18, MATCH(1, ($J32=$L$3:$L$18) * (M$25=$J$3:$J$18), 0)), "")} | O32: CSPA | P32: {=INDEX($G$1:$G$100, MATCH(1, ($A$1:$A$100=P$25)*($B$1:$B$100=$K9), 0))} -> 0.015432 | Q32: {=INDEX($G$1:$G$100, MATCH(1, ($A$1:$A$100=Q$25)*($B$1:$B$100=$K9), 0))} -> 0.020627 | R32: {=INDEX($G$1:$G$100, MATCH(1, ($A$1:$A$100=R$25)*($B$1:$B$100=$K9), 0))} -> 0.002807 | S32: {=INDEX($G$1:$G$100, MATCH(1, ($A$1:$A$100=S$25)*($B$1:$B$100=$K9), 0))} -> 0.008621 | T32: =IF(ISNA(N9), TRUE, ABS($M9-N9) > MAX($P32, Q32)) -> TRUE | U32: =IF(ISNA(O9), TRUE, ABS($M9-O9) > MAX($P32, R32)) -> TRUE | V32: =IF(ISNA(P9), TRUE, ABS($M9-P9) > MAX($P32, S32)) -> FALSE | X32: =IF(ISNA(N9), TRUE, ABS($P9-N9) > MAX($S32, Q32)) -> TRUE | Y32: =IF(ISNA(O9), TRUE, ABS($P9-O9) > MAX($S32, R32)) -> TRUE | Z32: =IF(ISNA(M9), TRUE, ABS($P9-M9) > MAX($S32, P32)) -> FALSE
A33: JDBC_RSQL | B33: tc | C33: avgt | D33: 1 | E33: 5 | F33: 0.004223 | G33: 0.004885 | H33: s/op | J33: CC | K33: {=IFERROR(INDEX($Q$3:$Q$18, MATCH(1, ($J33=$L$3:$L$18) * (K$25=$J$3:$J$18), 0)), "")} | L33: {=IFERROR(INDEX($Q$3:$Q$18, MATCH(1, ($J33=$L$3:$L$18) * (L$25=$J$3:$J$18), 0)), "")} -> 6.8156617 | M33: {=IFERROR(INDEX($Q$3:$Q$18, MATCH(1, ($J33=$L$3:$L$18) * (M$25=$J$3:$J$18), 0)), "")} | O33: Data Flow | P33: {=INDEX($G$1:$G$100, MATCH(1, ($A$1:$A$100=P$25)*($B$1:$B$100=$K10), 0))} -> 0.006625 | Q33: {=INDEX($G$1:$G$100, MATCH(1, ($A$1:$A$100=Q$25)*($B$1:$B$100=$K10), 0))} -> 0.027237 | R33: {=INDEX($G$1:$G$100, MATCH(1, ($A$1:$A$100=R$25)*($B$1:$B$100=$K10), 0))} -> 0.001093 | S33: {=INDEX($G$1:$G$100, MATCH(1, ($A$1:$A$100=S$25)*($B$1:$B$100=$K10), 0))} -> 0.004197 | T33: =IF(ISNA(N10), TRUE, ABS($M10-N10) > MAX($P33, Q33)) -> TRUE | U33: =IF(ISNA(O10), TRUE, ABS($M10-O10) > MAX($P33, R33)) -> FALSE | V33: =IF(ISNA(P10), TRUE, ABS($M10-P10) > MAX($P33, S33)) -> FALSE | X33: =IF(ISNA(N10), TRUE, ABS($P10-N10) > MAX($S33, Q33)) -> TRUE | Y33: =IF(ISNA(O10), TRUE, ABS($P10-O10) > MAX($S33, R33)) -> FALSE | Z33: =IF(ISNA(M10), TRUE, ABS($P10-M10) > MAX($S33, P33)) -> FALSE
A34: JDBC_RSQL | B34: trustchain | C34: avgt | D34: 1 | E34: 5 | F34: 0.007676 | G34: 0.004543 | H34: s/op | J34: COT | K34: {=IFERROR(INDEX($Q$3:$Q$18, MATCH(1, ($J34=$L$3:$L$18) * (K$25=$J$3:$J$18), 0)), "")} | L34: {=IFERROR(INDEX($Q$3:$Q$18, MATCH(1, ($J34=$L$3:$L$18) * (L$25=$J$3:$J$18), 0)), "")} -> 11.81531 | M34: {=IFERROR(INDEX($Q$3:$Q$18, MATCH(1, ($J34=$L$3:$L$18) * (M$25=$J$3:$J$18), 0)), "")} | O34: Even-Odd | P34: {=INDEX($G$1:$G$100, MATCH(1, ($A$1:$A$100=P$25)*($B$1:$B$100=$K11), 0))} -> 0.012256 | Q34: {=INDEX($G$1:$G$100, MATCH(1, ($A$1:$A$100=Q$25)*($B$1:$B$100=$K11), 0))} -> 0.038884 | R34: {=INDEX($G$1:$G$100, MATCH(1, ($A$1:$A$100=R$25)*($B$1:$B$100=$K11), 0))} -> 0.001979 | S34: {=INDEX($G$1:$G$100, MATCH(1, ($A$1:$A$100=S$25)*($B$1:$B$100=$K11), 0))} -> 0.01026 | T34: =IF(ISNA(N11), TRUE, ABS($M11-N11) > MAX($P34, Q34)) -> TRUE | U34: =IF(ISNA(O11), TRUE, ABS($M11-O11) > MAX($P34, R34)) -> FALSE | V34: =IF(ISNA(P11), TRUE, ABS($M11-P11) > MAX($P34, S34)) -> FALSE | X34: =IF(ISNA(N11), TRUE, ABS($P11-N11) > MAX($S34, Q34)) -> TRUE | Y34: =IF(ISNA(O11), TRUE, ABS($P11-O11) > MAX($S34, R34)) -> FALSE | Z34: =IF(ISNA(M11), TRUE, ABS($P11-M11) > MAX($S34, P34)) -> FALSE
A35: ScalaSQL | B35: ancestry | C35: avgt | D35: 1 | E35: 5 | F35: 0.044766 | G35: 0.013146 | H35: s/op | J35: CSPA | K35: {=IFERROR(INDEX($Q$3:$Q$18, MATCH(1, ($J35=$L$3:$L$18) * (K$25=$J$3:$J$18), 0)), "")} | L35: {=IFERROR(INDEX($Q$3:$Q$18, MATCH(1, ($J35=$L$3:$L$18) * (L$25=$J$3:$J$18), 0)), "")} -> 5.9027614 | M35: {=IFERROR(INDEX($Q$3:$Q$18, MATCH(1, ($J35=$L$3:$L$18) * (M$25=$J$3:$J$18), 0)), "")} | O35: JPT | P35: {=INDEX($G$1:$G$100, MATCH(1, ($A$1:$A$100=P$25)*($B$1:$B$100=$K12), 0))} -> 0.013006 | Q35: {=INDEX($G$1:$G$100, MATCH(1, ($A$1:$A$100=Q$25)*($B$1:$B$100=$K12), 0))} -> 0.024055 | R35: {=INDEX($G$1:$G$100, MATCH(1, ($A$1:$A$100=R$25)*($B$1:$B$100=$K12), 0))} -> 0.001068 | S35: {=INDEX($G$1:$G$100, MATCH(1, ($A$1:$A$100=S$25)*($B$1:$B$100=$K12), 0))} -> 0.009462 | T35: =IF(ISNA(N12), TRUE, ABS($M12-N12) > MAX($P35, Q35)) -> TRUE | U35: =IF(ISNA(O12), TRUE, ABS($M12-O12) > MAX($P35, R35)) -> TRUE | V35: =IF(ISNA(P12), TRUE, ABS($M12-P12) > MAX($P35, S35)) -> FALSE | X35: =IF(ISNA(N12), TRUE, ABS($P12-N12) > MAX($S35, Q35)) -> TRUE | Y35: =IF(ISNA(O12), TRUE, ABS($P12-O12) > MAX($S35, R35)) -> TRUE | Z35: =IF(ISNA(M12), TRUE, ABS($P12-M12) > MAX($S35, P35)) -> FALSE
A36: ScalaSQL | B36: andersens | C36: avgt | D36: 1 | E36: 5 | F36: 0.051443 | G36: 0.022573 | H36: s/op | J36: Even-Odd | K36: {=IFERROR(INDEX($Q$3:$Q$18, MATCH(1, ($J36=$L$3:$L$18) * (K$25=$J$3:$J$18), 0)), "")} | L36: {=IFERROR(INDEX($Q$3:$Q$18, MATCH(1, ($J36=$L$3:$L$18) * (L$25=$J$3:$J$18), 0)), "")} -> 26.313827 | M36: {=IFERROR(INDEX($Q$3:$Q$18, MATCH(1, ($J36=$L$3:$L$18) * (M$25=$J$3:$J$18), 0)), "")} | O36: Orbits | P36: {=INDEX($G$1:$G$100, MATCH(1, ($A$1:$A$100=P$25)*($B$1:$B$100=$K13), 0))} -> 0.005408 | Q36: {=INDEX($G$1:$G$100, MATCH(1, ($A$1:$A$100=Q$25)*($B$1:$B$100=$K13), 0))} -> 0.010548 | R36: {=INDEX($G$1:$G$100, MATCH(1, ($A$1:$A$100=R$25)*($B$1:$B$100=$K13), 0))} -> 0.001136 | S36: {=INDEX($G$1:$G$100, MATCH(1, ($A$1:$A$100=S$25)*($B$1:$B$100=$K13), 0))} -> 0.005045 | T36: =IF(ISNA(N13), TRUE, ABS($M13-N13) > MAX($P36, Q36)) -> TRUE | U36: =IF(ISNA(O13), TRUE, ABS($M13-O13) > MAX($P36, R36)) -> FALSE | V36: =IF(ISNA(P13), TRUE, ABS($M13-P13) > MAX($P36, S36)) -> FALSE | X36: =IF(ISNA(N13), TRUE, ABS($P13-N13) > MAX($S36, Q36)) -> TRUE | Y36: =IF(ISNA(O13), TRUE, ABS($P13-O13) > MAX($S36, R36)) -> FALSE | Z36: =IF(ISNA(M13), TRUE, ABS($P13-M13) > MAX($S36, P36)) -> FALSE
A37: ScalaSQL | B37: asps | C37: avgt | D37: 1 | E37: 5 | F37: 0.041396 | G37: 0.014372 | H37: s/op | J37: Orbits | K37: {=IFERROR(INDEX($Q$3:$Q$18, MATCH(1, ($J37=$L$3:$L$18) * (K$25=$J$3:$J$18), 0)), "")} | L37: {=IFERROR(INDEX($Q$3:$Q$18, MATCH(1, ($J37=$L$3:$L$18) * (L$25=$J$3:$J$18), 0)), "")} -> 5.4386169 | M37: {=IFERROR(INDEX($Q$3:$Q$18, MATCH(1, ($J37=$L$3:$L$18) * (M$25=$J$3:$J$18), 0)), "")} | O37: Party | P37: {=INDEX($G$1:$G$100, MATCH(1, ($A$1:$A$100=P$25)*($B$1:$B$100=$K14), 0))} -> 0.007185 | Q37: {=INDEX($G$1:$G$100, MATCH(1, ($A$1:$A$100=Q$25)*($B$1:$B$100=$K14), 0))} -> 0.015157 | R37: {=INDEX($G$1:$G$100, MATCH(1, ($A$1:$A$100=R$25)*($B$1:$B$100=$K14), 0))} -> 0.001945 | S37: {=INDEX($G$1:$G$100, MATCH(1, ($A$1:$A$100=S$25)*($B$1:$B$100=$K14), 0))} -> 0.004444 | T37: =IF(ISNA(N14), TRUE, ABS($M14-N14) > MAX($P37, Q37)) -> TRUE | U37: =IF(ISNA(O14), TRUE, ABS($M14-O14) > MAX($P37, R37)) -> FALSE | V37: =IF(ISNA(P14), TRUE, ABS($M14-P14) > MAX($P37, S37)) -> FALSE | X37: =IF(ISNA(N14), TRUE, ABS($P14-N14) > MAX($S37, Q37)) -> TRUE | Y37: =IF(ISNA(O14), TRUE, ABS($P14-O14) > MAX($S37, R37)) -> FALSE | Z37: =IF(ISNA(M14), TRUE, ABS($P14-M14) > MAX($S37, P37)) -> FALSE
... A41: ScalaSQL | B41: cspa | C41: avgt | D41: 1 | E41: 5 | F41: 0.155402 | G41: 0.020627 | H41: s/op | J41: TC | K41: {=IFERROR(INDEX($Q$3:$Q$18, MATCH(1, ($J41=$L$3:$L$18) * (K$25=$J$3:$J$18), 0)), "")} -> 3.3562744 | L41: {=IFERROR(INDEX($Q$3:$Q$18, MATCH(1, ($J41=$L$3:$L$18) * (L$25=$J$3:$J$18), 0)), "")} | M41: {=IFERROR(INDEX($Q$3:$Q$18, MATCH(1, ($J41=$L$3:$L$18) * (M$25=$J$3:$J$18), 0)), "")} | O41: COT | P41: {=INDEX($G$1:$G$100, MATCH(1, ($A$1:$A$100=P$25)*($B$1:$B$100=$K18), 0))} -> 0.006825 | Q41: {=INDEX($G$1:$G$100, MATCH(1, ($A$1:$A$100=Q$25)*($B$1:$B$100=$K18), 0))} -> 0.026071 | R41: {=INDEX($G$1:$G$100, MATCH(1, ($A$1:$A$100=R$25)*($B$1:$B$100=$K18), 0))} -> 0.001477 | S41: {=INDEX($G$1:$G$100, MATCH(1, ($A$1:$A$100=S$25)*($B$1:$B$100=$K18), 0))} -> 0.004543 | T41: =IF(ISNA(N18), TRUE, ABS($M18-N18) > MAX($P41, Q41)) -> TRUE | U41: =IF(ISNA(O18), TRUE, ABS($M18-O18) > MAX($P41, R41)) -> TRUE | V41: =IF(ISNA(P18), TRUE, ABS($M18-P18) > MAX($P41, S41)) -> FALSE | X41: =IF(ISNA(N18), TRUE, ABS($P18-N18) > MAX($S41, Q41)) -> TRUE | Y41: =IF(ISNA(O18), TRUE, ABS($P18-O18) > MAX($S41, R41)) -> TRUE | Z41: =IF(ISNA(M18), TRUE, ABS($P18-M18) > MAX($S41, P41)) -> FALSE
A42: ScalaSQL | B42: dataflow | C42: avgt | D42: 1 | E42: 5 | F42: 0.045449 | G42: 0.027237 | H42: s/op
A43: ScalaSQL | B43: evenodd | C43: avgt | D43: 1 | E43: 5 | F43: 0.294978 | G43: 0.038884 | H43: s/op | J43: COLLECTIONS
A44: ScalaSQL | B44: javapointsto | C44: avgt | D44: 1 | E44: 5 | F44: 0.071494 | G44: 0.024055 | H44: s/op | J44: Query | K44: Large | L44: Medium | M44: Small
A45: ScalaSQL | B45: orbits | C45: avgt | D45: 1 | E45: 5 | F45: 0.037434 | G45: 0.010548 | H45: s/op | J45: APT | K45: {=IFERROR(INDEX($R$3:$R$18, MATCH(1, ($J45=$L$3:$L$18) * (K$44=$J$3:$J$18), 0)), "")} | L45: {=IFERROR(INDEX($R$3:$R$18, MATCH(1, ($J45=$L$3:$L$18) * (L$44=$J$3:$J$18), 0)), "")} | M45: {=IFERROR(INDEX($R$3:$R$18, MATCH(1, ($J45=$L$3:$L$18) * (M$44=$J$3:$J$18), 0)), "")} -> 0.096982759
...

Sheet medium
A1: >> INPUT LARGE CLEANED CSV HERE | Q1: VS TYQL | T1: VS JDBC_RSQL
A2: Benchmark | B2: Mode | C2: Threads | D2: Samples | E2: Score | F2: Score Error (99.9%) | G2: Unit | J2: Size | K2: Query | L2: Formal Name | M2: TyQL | N2: ScalaSQL | O2: Collections | P2: JDBC_RSQL | Q2: Speedup over Non-Recursive SQL | R2: Speedup over Collections | S2: Speedup over JDBC_RSQL | U2: Speedup over Non-Recursive SQL | V2: Speedup over Collections | W2: Speedup over TyQL
