Workbook
Name feb14_repro48_large_iterations: large!$BE$2:$BG$175
Name feb14_repro48_medium_iterations: medium!$BB$2:$BD$231
Name feb21_rerun_jdbc48_large_clean: Sheet10!$U$1:$AB$50
Name feb21_rerun_jdbc48_medium_clean: Sheet10!$K$1:$R$56
Name feb21_rerun_jdbc48_small_clean: Sheet10!$A$1:$H$65
Name nov12_graal_data_10to_5x_8gb48_clean: small!$A$2:$H$34
Name nov12_graal_data_10to_5x_8gb48_iterations: small!$BF$1:$BH$321
Name nov12_large_graal_5x_8gb48_clean: large!$A$2:$H$19
Name nov12_large_graal_5x_8gb48_iterations: large!$BE$1:$BG$1
Name oct29_sized_3x47_clean: large!$A$2:$H$20
Name oct29_sized_3x47_clean: medium!$A$2:$H$2
Name oct29_sized_3x47_clean: small!#REF!
Name oct29_sized_3x48_clean: large!$A$2:$H$20
Name oct29_sized_3x48_clean: medium!$A$2:$H$2
Name oct29_sized_3x48_clean: small!#REF!

Sheet small
Q1: VS TYQL | T1: VS JDBC_RSQL | BF1: ancestry | BG1: collections | BH1: 3
A2: Backend | B2: Query | C2: Mode | D2: Threads | E2: Samples | F2: Score | G2: Score Error (99.9%) | H2: Unit | J2: Size | K2: Query | L2: Formal Name | M2: TyQL | N2: ScalaSQL | O2: Collections | P2: JDBC_RSQL | Q2: Speedup over Non-Recursive SQL | R2: Speedup over Collections | S2: Speedup over JDBC_RSQL | U2: Speedup over Non-Recursive SQL | V2: Speedup over Collections | W2: Speedup over TyQL | AC2: Average of 3 | AD2: Column Labels | BF2: ancestry | BG2: collections | BH2: 3
A3: Collections | B3: ancestry | C3: avgt | D3: 1 | E3: 5 | F3: 0.001878 | G3: 0.001387 | H3: s/op | J3: Large | K3: ancestry | L3: Ancestry | M3: {=INDEX($F$1:$F$100, MATCH(1, ($A$1:$A$100=M$2)*($B$1:$B$100=$K3), 0))} -> 0.007654 | N3: {=INDEX($F$1:$F$100, MATCH(1, (A$1:A$100=N$2)*(B$1:B$100=$K3), 0))} -> 0.046814 | O3: {=INDEX($F$1:$F$100, MATCH(1, (A$1:A$100=O$2)*(B$1:B$100=$K3), 0))} -> 0.001878 | P3: {=INDEX($F$1:$F$100, MATCH(1, (A$1:A$100=P$2)*(B$1:B$100=$K3), 0))} -> 0.005349 | Q3: =IF(ISNA($N3), "DNF", $N3/$M3) -> 6.1162791 | R3: =IF(ISNA(O3), "DNF", O3/$M3) -> 0.2453619 | S3: =IF(ISNA($P3), "DNF", $P3/$M3) -> 0.69885027 | U3: =IF(ISNA($N3), "DNF", $N3/$P3) -> 8.7519162 | V3: =IF(ISNA($O3), "DNF", $O3/$P3) -> 0.35109366 | W3: =IF(ISNA($M3), "DNF", $M3/$P3) -> 1.4309217 | AC3: Row Labels | AD3: collections | AE3: scalasql | BF3: ancestry | BG3: collections | BH3: 3
A4: Collections | B4: andersens | C4: avgt | D4: 1 | E4: 5 | F4: 0.001489 | G4: 0.001108 | H4: s/op | J4: Small | K4: andersens | L4: APT | M4: {=INDEX($F$1:$F$100, MATCH(1, (A$1:A$100=M$2)*(B$1:B$100=$K4), 0))} -> 0.013155 | N4: {=INDEX($F$1:$F$100, MATCH(1, (A$1:A$100=N$2)*(B$1:B$100=$K4), 0))} -> 0.054882 | O4: {=INDEX($F$1:$F$100, MATCH(1, (A$1:A$100=O$2)*(B$1:B$100=$K4), 0))} -> 0.001489 | P4: {=INDEX($F$1:$F$100, MATCH(1, (A$1:A$100=P$2)*(B$1:B$100=$K4), 0))} -> 0.011921 | Q4: =IF(ISNA($N4), "DNF", $N4/$M4) -> 4.1719498 | R4: =IF(ISNA(O4), "DNF", O4/$M4) -> 0.1131889 | S4: =IF(ISNA($P4), "DNF", $P4/$M4) -> 0.90619536 | U4: =IF(ISNA($N4), "DNF", $N4/$P4) -> 4.6038084 | V4: =IF(ISNA($O4), "DNF", $O4/$P4) -> 0.12490563 | W4: =IF(ISNA($M4), "DNF", $M4/$P4) -> 1.1035148 | AC4: ancestry | AD4: 3 | AE4: 3 | BF4: ancestry | BG4: collections | BH4: 3
A5: Collections | B5: asps | C5: avgt | D5: 1 | E5: 5 | F5: 0.003106 | G5: 0.003714 | H5: s/op | J5: Medium | K5: asps | L5: ASPS | M5: {=INDEX($F$1:$F$100, MATCH(1, (A$1:A$100=M$2)*(B$1:B$100=$K5), 0))} -> 0.012475 | N5: {=INDEX($F$1:$F$100, MATCH(1, (A$1:A$100=N$2)*(B$1:B$100=$K5), 0))} -> 0.043912 | O5: {=INDEX($F$1:$F$100, MATCH(1, (A$1:A$100=O$2)*(B$1:B$100=$K5), 0))} -> 0.003106 | P5: {=INDEX($F$1:$F$100, MATCH(1, (A$1:A$100=P$2)*(B$1:B$100=$K5), 0))} -> 0.011039 | Q5: =IF(ISNA($N5), "DNF", $N5/$M5) -> 3.52 | R5: =IF(ISNA(O5), "DNF", O5/$M5) -> 0.24897796 | S5: =IF(ISNA($P5), "DNF", $P5/$M5) -> 0.88488978 | U5: =IF(ISNA($N5), "DNF", $N5/$P5) -> 3.9778965 | V5: =IF(ISNA($O5), "DNF", $O5/$P5) -> 0.28136607 | W5: =IF(ISNA($M5), "DNF", $M5/$P5) -> 1.1300842 | AC5: andersens | AD5: 3 | AE5: 3 | BF5: ancestry | BG5: collections | BH5: 3
A6: Collections | B6: bom | C6: avgt | D6: 1 | E6: 5 | F6: 0.002131 | G6: 0.000857 | H6: s/op | J6: Medium | K6: bom | L6: BOM | M6: {=INDEX($F$1:$F$100, MATCH(1, (A$1:A$100=M$2)*(B$1:B$100=$K6), 0))} -> 0.008915 | N6: {=INDEX($F$1:$F$100, MATCH(1, (A$1:A$100=N$2)*(B$1:B$100=$K6), 0))} -> 0.035821 | O6: {=INDEX($F$1:$F$100, MATCH(1, (A$1:A$100=O$2)*(B$1:B$100=$K6), 0))} -> 0.002131 | P6: {=INDEX($F$1:$F$100, MATCH(1, (A$1:A$100=P$2)*(B$1:B$100=$K6), 0))} -> 0.00856 | Q6: =IF(ISNA($N6), "DNF", $N6/$M6) -> 4.0180595 | R6: =IF(ISNA(O6), "DNF", O6/$M6) -> 0.23903533 | S6: =IF(ISNA($P6), "DNF", $P6/$M6) -> 0.96017947 | U6: =IF(ISNA($N6), "DNF", $N6/$P6) -> 4.1846963 | V6: =IF(ISNA($O6), "DNF", $O6/$P6) -> 0.2489486 | W6: =IF(ISNA($M6), "DNF", $M6/$P6) -> 1.041472 | AC6: asps | AD6: 3 | AE6: 3 | BF6: ancestry | BG6: collections | BH6: 3
A7: Collections | B7: cba | C7: avgt | D7: 1 | E7: 5 | F7: 0.00617 | G7: 0.006925 | H7: s/op | J7: Small | K7: cba | L7: CBA | M7: {=INDEX($F$1:$F$100, MATCH(1, (A$1:A$100=M$2)*(B$1:B$100=$K7), 0))} -> 0.028225 | N7: {=INDEX($F$1:$F$100, MATCH(1, (A$1:A$100=N$2)*(B$1:B$100=$K7), 0))} -> 0.311347 | O7: {=INDEX($F$1:$F$100, MATCH(1, (A$1:A$100=O$2)*(B$1:B$100=$K7), 0))} -> 0.00617 | P7: {=INDEX($F$1:$F$100, MATCH(1, (A$1:A$100=P$2)*(B$1:B$100=$K7), 0))} -> 0.024934 | Q7: =IF(ISNA($N7), "DNF", $N7/$M7) -> 11.030895 | R7: =IF(ISNA(O7), "DNF", O7/$M7) -> 0.21860053 | S7: =IF(ISNA($P7), "DNF", $P7/$M7) -> 0.88340124 | U7: =IF(ISNA($N7), "DNF", $N7/$P7) -> 12.486845 | V7: =IF(ISNA($O7), "DNF", $O7/$P7) -> 0.24745328 | W7: =IF(ISNA($M7), "DNF", $M7/$P7) -> 1.1319884 | AC7: bom | AD7: 2 | AE7: 2 | BF7: ancestry | BG7: collections | BH7: 3
A8: Collections | B8: cc | C8: avgt | D8: 1 | E8: 5 | F8: 0.002427 | G8: 0.001144 | H8: s/op | J8: Medium | K8: cc | L8: CC | M8: {=INDEX($F$1:$F$100, MATCH(1, (A$1:A$100=M$2)*(B$1:B$100=$K8), 0))} -> 0.011314 | N8: {=INDEX($F$1:$F$100, MATCH(1, (A$1:A$100=N$2)*(B$1:B$100=$K8), 0))} -> 0.070066 | O8: {=INDEX($F$1:$F$100, MATCH(1, (A$1:A$100=O$2)*(B$1:B$100=$K8), 0))} -> 0.002427 | P8: {=INDEX($F$1:$F$100, MATCH(1, (A$1:A$100=P$2)*(B$1:B$100=$K8), 0))} -> 0.009234 | Q8: =IF(ISNA($N8), "DNF", $N8/$M8) -> 6.1928584 | R8: =IF(ISNA(O8), "DNF", O8/$M8) -> 0.21451299 | S8: =IF(ISNA($P8), "DNF", $P8/$M8) -> 0.81615697 | U8: =IF(ISNA($N8), "DNF", $N8/$P8) -> 7.5878276 | V8: =IF(ISNA($O8), "DNF", $O8/$P8) -> 0.26283301 | W8: =IF(ISNA($M8), "DNF", $M8/$P8) -> 1.2252545 | AC8: cba | AD8: 9 | AE8: 9 | BF8: ancestry | BG8: collections | BH8: 3
A9: Collections | B9: cspa | C9: avgt | D9: 1 | E9: 5 | F9: 0.002755 | G9: 0.002838 | H9: s/op | J9: Medium | K9: cspa | L9: CSPA | M9: {=INDEX($F$1:$F$100, MATCH(1, (A$1:A$100=M$2)*(B$1:B$100=$K9), 0))} -> 0.023838 | N9: {=INDEX($F$1:$F$100, MATCH(1, (A$1:A$100=N$2)*(B$1:B$100=$K9), 0))} -> 0.171146 | O9: {=INDEX($F$1:$F$100, MATCH(1, (A$1:A$100=O$2)*(B$1:B$100=$K9), 0))} -> 0.002755 | P9: {=INDEX($F$1:$F$100, MATCH(1, (A$1:A$100=P$2)*(B$1:B$100=$K9), 0))} -> 0.018014 | Q9: =IF(ISNA($N9), "DNF", $N9/$M9) -> 7.1795453 | R9: =IF(ISNA(O9), "DNF", O9/$M9) -> 0.11557178 | S9: =IF(ISNA($P9), "DNF", $P9/$M9) -> 0.7556842 | U9: =IF(ISNA($N9), "DNF", $N9/$P9) -> 9.5007217 | V9: =IF(ISNA($O9), "DNF", $O9/$P9) -> 0.1529366 | W9: =IF(ISNA($M9), "DNF", $M9/$P9) -> 1.3233041 | AC9: cc | AD9: 3 | AE9: 3 | BF9: ancestry | BG9: collections | BH9: 3
A10: Collections | B10: dataflow | C10: avgt | D10: 1 | E10: 5 | F10: 0.001989 | G10: 0.001504 | H10: s/op | J10: Small | K10: dataflow | L10: Data Flow | M10: {=INDEX($F$1:$F$100, MATCH(1, (A$1:A$100=M$2)*(B$1:B$100=$K10), 0))} -> 0.006463 | N10: {=INDEX($F$1:$F$100, MATCH(1, (A$1:A$100=N$2)*(B$1:B$100=$K10), 0))} -> 0.047777 | O10: {=INDEX($F$1:$F$100, MATCH(1, (A$1:A$100=O$2)*(B$1:B$100=$K10), 0))} -> 0.001989 | P10: {=INDEX($F$1:$F$100, MATCH(1, (A$1:A$100=P$2)*(B$1:B$100=$K10), 0))} -> 0.005227 | Q10: =IF(ISNA($N10), "DNF", $N10/$M10) -> 7.3923874 | R10: =IF(ISNA(O10), "DNF", O10/$M10) -> 0.30775182 | S10: =IF(ISNA($P10), "DNF", $P10/$M10) -> 0.80875754 | U10: =IF(ISNA($N10), "DNF", $N10/$P10) -> 9.1404247 | V10: =IF(ISNA($O10), "DNF", $O10/$P10) -> 0.3805242 | W10: =IF(ISNA($M10), "DNF", $M10/$P10) -> 1.2364645 | AC10: cspa | AD10: 3 | AE10: 5 | BF10: ancestry | BG10: collections | BH10: 3
A11: Collections | B11: evenodd | C11: avgt | D11: 1 | E11: 5 | F11: 0.004072 | G11: 0.003256 | H11: s/op | J11: Medium | K11: evenodd | L11: Even-Odd | M11: {=INDEX($F$1:$F$100, MATCH(1, (A$1:A$100=M$2)*(B$1:B$100=$K11), 0))} -> 0.013899 | N11: {=INDEX($F$1:$F$100, MATCH(1, (A$1:A$100=N$2)*(B$1:B$100=$K11), 0))} -> 0.327469 | O11: {=INDEX($F$1:$F$100, MATCH(1, (A$1:A$100=O$2)*(B$1:B$100=$K11), 0))} -> 0.004072 | P11: {=INDEX($F$1:$F$100, MATCH(1, (A$1:A$100=P$2)*(B$1:B$100=$K11), 0))} -> 0.008555 | Q11: =IF(ISNA($N11), "DNF", $N11/$M11) -> 23.560616 | R11: =IF(ISNA(O11), "DNF", O11/$M11) -> 0.29297072 | S11: =IF(ISNA($P11), "DNF", $P11/$M11) -> 0.61551191 | U11: =IF(ISNA($N11), "DNF", $N11/$P11) -> 38.278083 | V11: =IF(ISNA($O11), "DNF", $O11/$P11) -> 0.47597896 | W11: =IF(ISNA($M11), "DNF", $M11/$P11) -> 1.6246639 | AC11: dataflow | AD11: 3 | AE11: 3 | BF11: andersens | BG11: collections | BH11: 3
A12: Collections | B12: javapointsto | C12: avgt | D12: 1 | E12: 5 | F12: 0.002519 | G12: 0.001182 | H12: s/op | J12: Small | K12: javapointsto | L12: JPT | M12: {=INDEX($F$1:$F$100, MATCH(1, (A$1:A$100=M$2)*(B$1:B$100=$K12), 0))} -> 0.014302 | N12: {=INDEX($F$1:$F$100, MATCH(1, (A$1:A$100=N$2)*(B$1:B$100=$K12), 0))} -> 0.076816 | O12: {=INDEX($F$1:$F$100, MATCH(1, (A$1:A$100=O$2)*(B$1:B$100=$K12), 0))} -> 0.002519 | P12: {=INDEX($F$1:$F$100, MATCH(1, (A$1:A$100=P$2)*(B$1:B$100=$K12), 0))} -> 0.012098 | Q12: =IF(ISNA($N12), "DNF", $N12/$M12) -> 5.3709971 | R12: =IF(ISNA(O12), "DNF", O12/$M12) -> 0.17612921 | S12: =IF(ISNA($P12), "DNF", $P12/$M12) -> 0.84589568 | U12: =IF(ISNA($N12), "DNF", $N12/$P12) -> 6.3494793 | V12: =IF(ISNA($O12), "DNF", $O12/$P12) -> 0.20821623 | W12: =IF(ISNA($M12), "DNF", $M12/$P12) -> 1.1821789 | AC12: evenodd | AD12: 17 | AE12: 17 | BF12: andersens | BG12: collections | BH12: 3
A13: Collections | B13: orbits | C13: avgt | D13: 1 | E13: 5 | F13: 0.002048 | G13: 0.001137 | H13: s/op | J13: Medium | K13: orbits | L13: Orbits | M13: {=INDEX($F$1:$F$100, MATCH(1, (A$1:A$100=M$2)*(B$1:B$100=$K13), 0))} -> 0.011875 | N13: {=INDEX($F$1:$F$100, MATCH(1, (A$1:A$100=N$2)*(B$1:B$100=$K13), 0))} -> 0.037601 | O13: {=INDEX($F$1:$F$100, MATCH(1, (A$1:A$100=O$2)*(B$1:B$100=$K13), 0))} -> 0.002048 | P13: {=INDEX($F$1:$F$100, MATCH(1, (A$1:A$100=P$2)*(B$1:B$100=$K13), 0))} -> 0.00955 | Q13: =IF(ISNA($N13), "DNF", $N13/$M13) -> 3.1664 | R13: =IF(ISNA(O13), "DNF", O13/$M13) -> 0.17246316 | S13: =IF(ISNA($P13), "DNF", $P13/$M13) -> 0.80421053 | U13: =IF(ISNA($N13), "DNF", $N13/$P13) -> 3.9372775 | V13: =IF(ISNA($O13), "DNF", $O13/$P13) -> 0.21445026 | W13: =IF(ISNA($M13), "DNF", $M13/$P13) -> 1.2434555 | AC13: javapointsto | AD13: 3 | AE13: 3 | BF13: andersens | BG13: collections | BH13: 3
A14: Collections | B14: party | C14: avgt | D14: 1 | E14: 5 | F14: 0.003742 | G14: 0.002275 | H14: s/op | J14: Medium | K14: party | L14: Party | M14: {=INDEX($F$1:$F$100, MATCH(1, (A$1:A$100=M$2)*(B$1:B$100=$K14), 0))} -> 0.011764 | N14: {=INDEX($F$1:$F$100, MATCH(1, (A$1:A$100=N$2)*(B$1:B$100=$K14), 0))} -> 0.098845 | O14: {=INDEX($F$1:$F$100, MATCH(1, (A$1:A$100=O$2)*(B$1:B$100=$K14), 0))} -> 0.003742 | P14: {=INDEX($F$1:$F$100, MATCH(1, (A$1:A$100=P$2)*(B$1:B$100=$K14), 0))} -> 0.009801 | Q14: =IF(ISNA($N14), "DNF", $N14/$M14) -> 8.4023291 | R14: =IF(ISNA(O14), "DNF", O14/$M14) -> 0.31808909 | S14: =IF(ISNA($P14), "DNF", $P14/$M14) -> 0.83313499 | U14: =IF(ISNA($N14), "DNF", $N14/$P14) -> 10.085195 | V14: =IF(ISNA($O14), "DNF", $O14/$P14) -> 0.38179778 | W14: =IF(ISNA($M14), "DNF", $M14/$P14) -> 1.2002857 | AC14: orbits | AD14: 2 | AE14: 2 | BF14: andersens | BG14: collections | BH14: 3
A15: Collections | B15: pointstocount | C15: avgt | D15: 1 | E15: 5 | F15: 0.002606 | G15: 0.000467 | H15: s/op | J15: Small | K15: pointstocount | L15: PTC | M15: {=INDEX($F$1:$F$100, MATCH(1, (A$1:A$100=M$2)*(B$1:B$100=$K15), 0))} -> 0.016161 | N15: {=INDEX($F$1:$F$100, MATCH(1, (A$1:A$100=N$2)*(B$1:B$100=$K15), 0))} -> 0.084974 | O15: {=INDEX($F$1:$F$100, MATCH(1, (A$1:A$100=O$2)*(B$1:B$100=$K15), 0))} -> 0.002606 | P15: {=INDEX($F$1:$F$100, MATCH(1, (A$1:A$100=P$2)*(B$1:B$100=$K15), 0))} -> 0.012428 | Q15: =IF(ISNA($N15), "DNF", $N15/$M15) -> 5.2579667 | R15: =IF(ISNA(O15), "DNF", O15/$M15) -> 0.1612524 | S15: =IF(ISNA($P15), "DNF", $P15/$M15) -> 0.76901182 | U15: =IF(ISNA($N15), "DNF", $N15/$P15) -> 6.8373029 | V15: =IF(ISNA($O15), "DNF", $O15/$P15) -> 0.2096878 | W15: =IF(ISNA($M15), "DNF", $M15/$P15) -> 1.3003701 | AC15: party | AD15: 5 | AE15: 5 | BF15: andersens | BG15: collections | BH15: 3
... A18: Collections | B18: trustchain | C18: avgt | D18: 1 | E18: 5 | F18: 0.002866 | G18: 0.001287 | H18: s/op | J18: Medium | K18: trustchain | L18: COT | M18: {=INDEX($F$1:$F$100, MATCH(1, (A$1:A$100=M$2)*(B$1:B$100=$K18), 0))} -> 0.011426 | N18: {=INDEX($F$1:$F$100, MATCH(1, (A$1:A$100=N$2)*(B$1:B$100=$K18), 0))} -> 0.15993 | O18: {=INDEX($F$1:$F$100, MATCH(1, (A$1:A$100=O$2)*(B$1:B$100=$K18), 0))} -> 0.002866 | P18: {=INDEX($F$1:$F$100, MATCH(1, (A$1:A$100=P$2)*(B$1:B$100=$K18), 0))} -> 0.008272 | Q18: =IF(ISNA($N18), "DNF", $N18/$M18) -> 13.997024 | R18: =IF(ISNA(O18), "DNF", O18/$M18) -> 0.25083144 | S18: =IF(ISNA($P18), "DNF", $P18/$M18) -> 0.72396289 | U18: =IF(ISNA($N18), "DNF", $N18/$P18) -> 19.333897 | V18: =IF(ISNA($O18), "DNF", $O18/$P18) -> 0.34647002 | W18: =IF(ISNA($M18), "DNF", $M18/$P18) -> 1.3812863 | AC18: tc | AD18: 2 | AE18: 2 | BF18: andersens | BG18: collections | BH18: 3
A19: JDBC_RSQL | B19: ancestry | C19: avgt | D19: 1 | E19: 5 | F19: 0.005349 | G19: 0.003112 | H19: s/op | AC19: trustchain | AD19: 7 | AE19: 7 | BF19: andersens | BG19: collections | BH19: 3
A20: JDBC_RSQL | B20: andersens | C20: avgt | D20: 1 | E20: 5 | F20: 0.011921 | G20: 0.004856 | H20: s/op | BF20: andersens | BG20: collections | BH20: 3
A21: JDBC_RSQL | B21: asps | C21: avgt | D21: 1 | E21: 5 | F21: 0.011039 | G21: 0.007173 | H21: s/op | BF21: asps | BG21: collections | BH21: 3
A22: JDBC_RSQL | B22: bom | C22: avgt | D22: 1 | E22: 5 | F22: 0.00856 | G22: 0.005311 | H22: s/op | BF22: asps | BG22: collections | BH22: 3
A23: JDBC_RSQL | B23: cba | C23: avgt | D23: 1 | E23: 5 | F23: 0.024934 | G23: 0.009926 | H23: s/op | BF23: asps | BG23: collections | BH23: 3
A24: JDBC_RSQL | B24: cc | C24: avgt | D24: 1 | E24: 5 | F24: 0.009234 | G24: 0.005463 | H24: s/op | J24: SCALASQL | P24: Margin of Error: | T24: TYQL Speedup exceeds error margin? | X24: JDBC_RSQL Speedup exceeds error margin? | BF24: asps | BG24: collections | BH24: 3
A25: JDBC_RSQL | B25: cspa | C25: avgt | D25: 1 | E25: 5 | F25: 0.018014 | G25: 0.006683 | H25: s/op | J25: Query | K25: Large | L25: Medium | M25: Small | O25: Formal Name | P25: TyQL | Q25: ScalaSQL | R25: Collections | S25: JDBC_RSQL | T25: SCALASQL | U25: COLLECTIONS | V25: JDBC_RSQL | X25: SCALASQL | Y25: COLLECTIONS | Z25: TyQL | BF25: asps | BG25: collections | BH25: 3
A26: JDBC_RSQL | B26: dataflow | C26: avgt | D26: 1 | E26: 5 | F26: 0.005227 | G26: 0.002999 | H26: s/op | J26: APT | K26: {=IFERROR(INDEX($Q$3:$Q$18, MATCH(1, ($J26=$L$3:$L$18) * (K$25=$J$3:$J$18), 0)), "")} | L26: {=IFERROR(INDEX($Q$3:$Q$18, MATCH(1, ($J26=$L$3:$L$18) * (L$25=$J$3:$J$18), 0)), "")} | M26: {=IFERROR(INDEX($Q$3:$Q$18, MATCH(1, ($J26=$L$3:$L$18) * (M$25=$J$3:$J$18), 0)), "")} -> 4.1719498 | O26: Ancestry | P26: {=INDEX($G$1:$G$100, MATCH(1, ($A$1:$A$100=P$25)*($B$1:$B$100=$K3), 0))} -> 0.005794 | Q26: {=INDEX($G$1:$G$100, MATCH(1, ($A$1:$A$100=Q$25)*($B$1:$B$100=$K3), 0))} -> 0.013365 | R26: {=INDEX($G$1:$G$100, MATCH(1, ($A$1:$A$100=R$25)*($B$1:$B$100=$K3), 0))} -> 0.001387 | S26: {=INDEX($G$1:$G$100, MATCH(1, ($A$1:$A$100=S$25)*($B$1:$B$100=$K3), 0))} -> 0.003112 | T26: =IF(ISNA(N3), TRUE, ABS($M3-N3) > MAX($P26, Q26)) -> TRUE | U26: =IF(ISNA(O3), TRUE, ABS($M3-O3) > MAX($P26, R26)) -> FALSE | V26: =IF(ISNA(P3), TRUE, ABS($M3-P3) > MAX($P26, S26)) -> FALSE | X26: =IF(ISNA(N3), TRUE, ABS($P3-N3) > MAX($S26, Q26)) -> TRUE | Y26: =IF(ISNA(O3), TRUE, ABS($P3-O3) > MAX($S26, R26)) -> TRUE | Z26: =IF(ISNA(M3), TRUE, ABS($P3-M3) > MAX($S26, P26)) -> FALSE | BF26: asps | BG26: collections | BH26: 3
A27: JDBC_RSQL | B27: evenodd | C27: avgt | D27: 1 | E27: 5 | F27: 0.008555 | G27: 0.00286 | H27: s/op | J27: CBA | K27: {=IFERROR(INDEX($Q$3:$Q$18, MATCH(1, ($J27=$L$3:$L$18) * (K$25=$J$3:$J$18), 0)), "")} | L27: {=IFERROR(INDEX($Q$3:$Q$18, MATCH(1, ($J27=$L$3:$L$18) * (L$25=$J$3:$J$18), 0)), "")} | M27: {=IFERROR(INDEX($Q$3:$Q$18, MATCH(1, ($J27=$L$3:$L$18) * (M$25=$J$3:$J$18), 0)), "")} -> 11.030895 | O27: APT | P27: {=INDEX($G$1:$G$100, MATCH(1, ($A$1:$A$100=P$25)*($B$1:$B$100=$K4), 0))} -> 0.010588 | Q27: {=INDEX($G$1:$G$100, MATCH(1, ($A$1:$A$100=Q$25)*($B$1:$B$100=$K4), 0))} -> 0.021817 | R27: {=INDEX($G$1:$G$100, MATCH(1, ($A$1:$A$100=R$25)*($B$1:$B$100=$K4), 0))} -> 0.001108 | S27: {=INDEX($G$1:$G$100, MATCH(1, ($A$1:$A$100=S$25)*($B$1:$B$100=$K4), 0))} -> 0.004856 | T27: =IF(ISNA(N4), TRUE, ABS($M4-N4) > MAX($P27, Q27)) -> TRUE | U27: =IF(ISNA(O4), TRUE, ABS($M4-O4) > MAX($P27, R27)) -> TRUE | V27: =IF(ISNA(P4), TRUE, ABS($M4-P4) > MAX($P27, S27)) -> FALSE | X27: =IF(ISNA(N4), TRUE, ABS($P4-N4) > MAX($S27, Q27)) -> TRUE | Y27: =IF(ISNA(O4), TRUE, ABS($P4-O4) > MAX($S27, R27)) -> TRUE | Z27: =IF(ISNA(M4), TRUE, ABS($P4-M4) > MAX($S27, P27)) -> FALSE | BF27: asps | BG27: collections | BH27: 3
A28: JDBC_RSQL | B28: javapointsto | C28: avgt | D28: 1 | E28: 5 | F28: 0.012098 | G28: 0.007275 | H28: s/op | J28: Data Flow | K28: {=IFERROR(INDEX($Q$3:$Q$18, MATCH(1, ($J28=$L$3:$L$18) * (K$25=$J$3:$J$18), 0)), "")} | L28: {=IFERROR(INDEX($Q$3:$Q$18, MATCH(1, ($J28=$L$3:$L$18) * (L$25=$J$3:$J$18), 0)), "")} | M28: {=IFERROR(INDEX($Q$3:$Q$18, MATCH(1, ($J28=$L$3:$L$18) * (M$25=$J$3:$J$18), 0)), "")} -> 7.3923874 | O28: ASPS | P28: {=INDEX($G$1:$G$100, MATCH(1, ($A$1:$A$100=P$25)*($B$1:$B$100=$K5), 0))} -> 0.01051 | Q28: {=INDEX($G$1:$G$100, MATCH(1, ($A$1:$A$100=Q$25)*($B$1:$B$100=$K5), 0))} -> 0.011979 | R28: {=INDEX($G$1:$G$100, MATCH(1, ($A$1:$A$100=R$25)*($B$1:$B$100=$K5), 0))} -> 0.003714 | S28: {=INDEX($G$1:$G$100, MATCH(1, ($A$1:$A$100=S$25)*($B$1:$B$100=$K5), 0))} -> 0.007173 | T28: =IF(ISNA(N5), TRUE, ABS($M5-N5) > MAX($P28, Q28)) -> TRUE | U28: =IF(ISNA(O5), TRUE, ABS($M5-O5) > MAX($P28, R28)) -> FALSE | V28: =IF(ISNA(P5), TRUE, ABS($M5-P5) > MAX($P28, S28)) -> FALSE | X28: =IF(ISNA(N5), TRUE, ABS($P5-N5) > MAX($S28, Q28)) -> TRUE | Y28: =IF(ISNA(O5), TRUE, ABS($P5-O5) > MAX($S28, R28)) -> TRUE | Z28: =IF(ISNA(M5), TRUE, ABS($P5-M5) > MAX($S28, P28)) -> FALSE | BF28: asps | BG28: collections | BH28: 3
A29: JDBC_RSQL | B29: orbits | C29: avgt | D29: 1 | E29: 5 | F29: 0.00955 | G29: 0.005783 | H29: s/op | J29: JPT | K29: {=IFERROR(INDEX($Q$3:$Q$18, MATCH(1, ($J29=$L$3:$L$18) * (K$25=$J$3:$J$18), 0)), "")} | L29: {=IFERROR(INDEX($Q$3:$Q$18, MATCH(1, ($J29=$L$3:$L$18) * (L$25=$J$3:$J$18), 0)), "")} | M29: {=IFERROR(INDEX($Q$3:$Q$18, MATCH(1, ($J29=$L$3:$L$18) * (M$25=$J$3:$J$18), 0)), "")} -> 5.3709971 | O29: BOM | P29: {=INDEX($G$1:$G$100, MATCH(1, ($A$1:$A$100=P$25)*($B$1:$B$100=$K6), 0))} -> 0.008805 | Q29: {=INDEX($G$1:$G$100, MATCH(1, ($A$1:$A$100=Q$25)*($B$1:$B$100=$K6), 0))} -> 0.01291 | R29: {=INDEX($G$1:$G$100, MATCH(1, ($A$1:$A$100=R$25)*($B$1:$B$100=$K6), 0))} -> 0.000857 | S29: {=INDEX($G$1:$G$100, MATCH(1, ($A$1:$A$100=S$25)*($B$1:$B$100=$K6), 0))} -> 0.005311 | T29: =IF(ISNA(N6), TRUE, ABS($M6-N6) > MAX($P29, Q29)) -> TRUE | U29: =IF(ISNA(O6), TRUE, ABS($M6-O6) > MAX($P29, R29)) -> FALSE | V29: =IF(ISNA(P6), TRUE, ABS($M6-P6) > MAX($P29, S29)) -> FALSE | X29: =IF(ISNA(N6), TRUE, ABS($P6-N6) > MAX($S29, Q29)) -> TRUE | Y29: =IF(ISNA(O6), TRUE, ABS($P6-O6) > MAX($S29, R29)) -> TRUE | Z29: =IF(ISNA(M6), TRUE, ABS($P6-M6) > MAX($S29, P29)) -> FALSE | BF29: asps | BG29: collections | BH29: 3
A30: JDBC_RSQL | B30: party | C30: avgt | D30: 1 | E30: 5 | F30: 0.009801 | G30: 0.007748 | H30: s/op | J30: PTC | K30: {=IFERROR(INDEX($Q$3:$Q$18, MATCH(1, ($J30=$L$3:$L$18) * (K$25=$J$3:$J$18), 0)), "")} | L30: {=IFERROR(INDEX($Q$3:$Q$18, MATCH(1, ($J30=$L$3:$L$18) * (L$25=$J$3:$J$18), 0)), "")} | M30: {=IFERROR(INDEX($Q$3:$Q$18, MATCH(1, ($J30=$L$3:$L$18) * (M$25=$J$3:$J$18), 0)), "")} -> 5.2579667 | O30: CBA | P30: {=INDEX($G$1:$G$100, MATCH(1, ($A$1:$A$100=P$25)*($B$1:$B$100=$K7), 0))} -> 0.012089 | Q30: {=INDEX($G$1:$G$100, MATCH(1, ($A$1:$A$100=Q$25)*($B$1:$B$100=$K7), 0))} -> 0.036797 | R30: {=INDEX($G$1:$G$100, MATCH(1, ($A$1:$A$100=R$25)*($B$1:$B$100=$K7), 0))} -> 0.006925 | S30: {=INDEX($G$1:$G$100, MATCH(1, ($A$1:$A$100=S$25)*($B$1:$B$100=$K7), 0))} -> 0.009926 | T30: =IF(ISNA(N7), TRUE, ABS($M7-N7) > MAX($P30, Q30)) -> TRUE | U30: =IF(ISNA(O7), TRUE, ABS($M7-O7) > MAX($P30, R30)) -> TRUE | V30: =IF(ISNA(P7), TRUE, ABS($M7-P7) > MAX($P30, S30)) -> FALSE | X30: =IF(ISNA(N7), TRUE, ABS($P7-N7) > MAX($S30, Q30)) -> TRUE | Y30: =IF(ISNA(O7), TRUE, ABS($P7-O7) > MAX($S30, R30)) -> TRUE | Z30: =IF(ISNA(M7), TRUE, ABS($P7-M7) > MAX($S30, P30)) -> FALSE | BF30: asps | BG30: collections | BH30: 3
A31: JDBC_RSQL | B31: pointstocount | C31: avgt | D31: 1 | E31: 5 | F31: 0.012428 | G31: 0.008041 | H31: s/op | J31: ASPS | K31: {=IFERROR(INDEX($Q$3:$Q$18, MATCH(1, ($J31=$L$3:$L$18) * (K$25=$J$3:$J$18), 0)), "")} | L31: {=IFERROR(INDEX($Q$3:$Q$18, MATCH(1, ($J31=$L$3:$L$18) * (L$25=$J$3:$J$18), 0)), "")} -> 3.52 | M31: {=IFERROR(INDEX($Q$3:$Q$18, MATCH(1, ($J31=$L$3:$L$18) * (M$25=$J$3:$J$18), 0)), "")} | O31: CC | P31: {=INDEX($G$1:$G$100, MATCH(1, ($A$1:$A$100=P$25)*($B$1:$B$100=$K8), 0))} -> 0.005356 | Q31: {=INDEX($G$1:$G$100, MATCH(1, ($A$1:$A$100=Q$25)*($B$1:$B$100=$K8), 0))} -> 0.019456 | R31: {=INDEX($G$1:$G$100, MATCH(1, ($A$1:$A$100=R$25)*($B$1:$B$100=$K8), 0))} -> 0.001144 | S31: {=INDEX($G$1:$G$100, MATCH(1, ($A$1:$A$100=S$25)*($B$1:$B$100=$K8), 0))} -> 0.005463 | T31: =IF(ISNA(N8), TRUE, ABS($M8-N8) > MAX($P31, Q31)) -> TRUE | U31: =IF(ISNA(O8), TRUE, ABS($M8-O8) > MAX($P31, R31)) -> TRUE | V31: =IF(ISNA(P8), TRUE, ABS($M8-P8) > MAX($P31, S31)) -> FALSE | X31: =IF(ISNA(N8), TRUE, ABS($P8-N8) > MAX($S31, Q31)) -> TRUE | Y31: =IF(ISNA(O8), TRUE, ABS($P8-O8) > MAX($S31, R31)) -> TRUE | Z31: =IF(ISNA(M8), TRUE, ABS($P8-M8) > MAX($S31, P31)) -> FALSE | BF31: bom | BG31: collections | BH31: 2
A32: JDBC_RSQL | B32: sssp | C32: avgt | D32: 1 | E32: 5 | F32: 0.008624 | G32: 0.006822 | H32: s/op | J32: BOM | K32: {=IFERROR(INDEX($Q$3:$Q$18, MATCH(1, ($J32=$L$3:$L$18) * (K$25=$J$3:$J$18), 0)), "")} | L32: {=IFERROR(INDEX($Q$3:$Q$18, MATCH(1, ($J32=$L$3:$L$18) * (L$25=$J$3:$J$18), 0)), "")} -> 4.0180595 | M32: {=IFERROR(INDEX($Q$3:$Q$18, MATCH(1, ($J32=$L$3:$L$18) * (M$25=$J$3:$J$18), 0)), "")} | O32: CSPA | P32: {=INDEX($G$1:$G$100, MATCH(1, ($A$1:$A$100=P$25)*($B$1:$B$100=$K9), 0))} -> 0.009153 | Q32: {=INDEX($G$1:$G$100, MATCH(1, ($A$1:$A$100=Q$25)*($B$1:$B$100=$K9), 0))} -> 0.023592 | R32: {=INDEX($G$1:$G$100, MATCH(1, ($A$1:$A$100=R$25)*($B$1:$B$100=$K9), 0))} -> 0.002838 | S32: {=INDEX($G$1:$G$100, MATCH(1, ($A$1:$A$100=S$25)*($B$1:$B$100=$K9), 0))} -> 0.006683 | T32: =IF(ISNA(N9), TRUE, ABS($M9-N9) > MAX($P32, Q32)) -> TRUE | U32: =IF(ISNA(O9), TRUE, ABS($M9-O9) > MAX($P32, R32)) -> TRUE | V32: =IF(ISNA(P9), TRUE, ABS($M9-P9) > MAX($P32, S32)) -> FALSE | X32: =IF(ISNA(N9), TRUE, ABS($P9-N9) > MAX($S32, Q32)) -> TRUE | Y32: =IF(ISNA(O9), TRUE, ABS($P9-O9) > MAX($S32, R32)) -> TRUE | Z32: =IF(ISNA(M9), TRUE, ABS($P9-M9) > MAX($S32, P32)) -> FALSE | BF32: bom | BG32: collections | BH32: 2
A33: JDBC_RSQL | B33: tc | C33: avgt | D33: 1 | E33: 5 | F33: 0.004989 | G33: 0.002773 | H33: s/op | J33: CC | K33: {=IFERROR(INDEX($Q$3:$Q$18, MATCH(1, ($J33=$L$3:$L$18) * (K$25=$J$3:$J$18), 0)), "")} | L33: {=IFERROR(INDEX($Q$3:$Q$18, MATCH(1, ($J33=$L$3:$L$18) * (L$25=$J$3:$J$18), 0)), "")} -> 6.1928584 | M33: {=IFERROR(INDEX($Q$3:$Q$18, MATCH(1, ($J33=$L$3:$L$18) * (M$25=$J$3:$J$18), 0)), "")} | O33: Data Flow | P33: {=INDEX($G$1:$G$100, MATCH(1, ($A$1:$A$100=P$25)*($B$1:$B$100=$K10), 0))} -> 0.001824 | Q33: {=INDEX($G$1:$G$100, MATCH(1, ($A$1:$A$100=Q$25)*($B$1:$B$100=$K10), 0))} -> 0.005801 | R33: {=INDEX($G$1:$G$100, MATCH(1, ($A$1:$A$100=R$25)*($B$1:$B$100=$K10), 0))} -> 0.001504 | S33: {=INDEX($G$1:$G$100, MATCH(1, ($A$1:$A$100=S$25)*($B$1:$B$100=$K10), 0))} -> 0.002999 | T33: =IF(ISNA(N10), TRUE, ABS($M10-N10) > MAX($P33, Q33)) -> TRUE | U33: =IF(ISNA(O10), TRUE, ABS($M10-O10) > MAX($P33, R33)) -> TRUE | V33: =IF(ISNA(P10), TRUE, ABS($M10-P10) > MAX($P33, S33)) -> FALSE | X33: =IF(ISNA(N10), TRUE, ABS($P10-N10) > MAX($S33, Q33)) -> TRUE | Y33: =IF(ISNA(O10), TRUE, ABS($P10-O10) > MAX($S33, R33)) -> TRUE | Z33: =IF(ISNA(M10), TRUE, ABS($P10-M10) > MAX($S33, P33)) -> FALSE | BF33: bom | BG33: collections | BH33: 2
A34: JDBC_RSQL | B34: trustchain | C34: avgt | D34: 1 | E34: 5 | F34: 0.008272 | G34: 0.003313 | H34: s/op | J34: COT | K34: {=IFERROR(INDEX($Q$3:$Q$18, MATCH(1, ($J34=$L$3:$L$18) * (K$25=$J$3:$J$18), 0)), "")} | L34: {=IFERROR(INDEX($Q$3:$Q$18, MATCH(1, ($J34=$L$3:$L$18) * (L$25=$J$3:$J$18), 0)), "")} -> 13.997024 | M34: {=IFERROR(INDEX($Q$3:$Q$18, MATCH(1, ($J34=$L$3:$L$18) * (M$25=$J$3:$J$18), 0)), "")} | O34: Even-Odd | P34: {=INDEX($G$1:$G$100, MATCH(1, ($A$1:$A$100=P$25)*($B$1:$B$100=$K11), 0))} -> 0.005966 | Q34: {=INDEX($G$1:$G$100, MATCH(1, ($A$1:$A$100=Q$25)*($B$1:$B$100=$K11), 0))} -> 0.031792 | R34: {=INDEX($G$1:$G$100, MATCH(1, ($A$1:$A$100=R$25)*($B$1:$B$100=$K11), 0))} -> 0.003256 | S34: {=INDEX($G$1:$G$100, MATCH(1, ($A$1:$A$100=S$25)*($B$1:$B$100=$K11), 0))} -> 0.00286 | T34: =IF(ISNA(N11), TRUE, ABS($M11-N11) > MAX($P34, Q34)) -> TRUE | U34: =IF(ISNA(O11), TRUE, ABS($M11-O11) > MAX($P34, R34)) -> TRUE | V34: =IF(ISNA(P11), TRUE, ABS($M11-P11) > MAX($P34, S34)) -> FALSE | X34: =IF(ISNA(N11), TRUE, ABS($P11-N11) > MAX($S34, Q34)) -> TRUE | Y34: =IF(ISNA(O11), TRUE, ABS($P11-O11) > MAX($S34, R34)) -> TRUE | Z34: =IF(ISNA(M11), TRUE, ABS($P11-M11) > MAX($S34, P34)) -> FALSE | BF34: bom | BG34: collections | BH34: 2
A35: ScalaSQL | B35: ancestry | C35: avgt | D35: 1 | E35: 5 | F35: 0.046814 | G35: 0.013365 | H35: s/op | J35: CSPA | K35: {=IFERROR(INDEX($Q$3:$Q$18, MATCH(1, ($J35=$L$3:$L$18) * (K$25=$J$3:$J$18), 0)), "")} | L35: {=IFERROR(INDEX($Q$3:$Q$18, MATCH(1, ($J35=$L$3:$L$18) * (L$25=$J$3:$J$18), 0)), "")} -> 7.1795453 | M35: {=IFERROR(INDEX($Q$3:$Q$18, MATCH(1, ($J35=$L$3:$L$18) * (M$25=$J$3:$J$18), 0)), "")} | O35: JPT | P35: {=INDEX($G$1:$G$100, MATCH(1, ($A$1:$A$100=P$25)*($B$1:$B$100=$K12), 0))} -> 0.007393 | Q35: {=INDEX($G$1:$G$100, MATCH(1, ($A$1:$A$100=Q$25)*($B$1:$B$100=$K12), 0))} -> 0.016328 | R35: {=INDEX($G$1:$G$100, MATCH(1, ($A$1:$A$100=R$25)*($B$1:$B$100=$K12), 0))} -> 0.001182 | S35: {=INDEX($G$1:$G$100, MATCH(1, ($A$1:$A$100=S$25)*($B$1:$B$100=$K12), 0))} -> 0.007275 | T35: =IF(ISNA(N12), TRUE, ABS($M12-N12) > MAX($P35, Q35)) -> TRUE | U35: =IF(ISNA(O12), TRUE, ABS($M12-O12) > MAX($P35, R35)) -> TRUE | V35: =IF(ISNA(P12), TRUE, ABS($M12-P12) > MAX($P35, S35)) -> FALSE | X35: =IF(ISNA(N12), TRUE, ABS($P12-N12) > MAX($S35, Q35)) -> TRUE | Y35: =IF(ISNA(O12), TRUE, ABS($P12-O12) > MAX($S35, R35)) -> TRUE | Z35: =IF(ISNA(M12), TRUE, ABS($P12-M12) > MAX($S35, P35)) -> FALSE | BF35: bom | BG35: collections | BH35: 2
A36: ScalaSQL | B36: andersens | C36: avgt | D36: 1 | E36: 5 | F36: 0.054882 | G36: 0.021817 | H36: s/op | J36: Even-Odd | K36: {=IFERROR(INDEX($Q$3:$Q$18, MATCH(1, ($J36=$L$3:$L$18) * (K$25=$J$3:$J$18), 0)), "")} | L36: {=IFERROR(INDEX($Q$3:$Q$18, MATCH(1, ($J36=$L$3:$L$18) * (L$25=$J$3:$J$18), 0)), "")} -> 23.560616 | M36: {=IFERROR(INDEX($Q$3:$Q$18, MATCH(1, ($J36=$L$3:$L$18) * (M$25=$J$3:$J$18), 0)), "")} | O36: Orbits | P36: {=INDEX($G$1:$G$100, MATCH(1, ($A$1:$A$100=P$25)*($B$1:$B$100=$K13), 0))} -> 0.009846 | Q36: {=INDEX($G$1:$G$100, MATCH(1, ($A$1:$A$100=Q$25)*($B$1:$B$100=$K13), 0))} -> 0.006033 | R36: {=INDEX($G$1:$G$100, MATCH(1, ($A$1:$A$100=R$25)*($B$1:$B$100=$K13), 0))} -> 0.001137 | S36: {=INDEX($G$1:$G$100, MATCH(1, ($A$1:$A$100=S$25)*($B$1:$B$100=$K13), 0))} -> 0.005783 | T36: =IF(ISNA(N13), TRUE, ABS($M13-N13) > MAX($P36, Q36)) -> TRUE | U36: =IF(ISNA(O13), TRUE, ABS($M13-O13) > MAX($P36, R36)) -> FALSE | V36: =IF(ISNA(P13), TRUE, ABS($M13-P13) > MAX($P36, S36)) -> FALSE | X36: =IF(ISNA(N13), TRUE, ABS($P13-N13) > MAX($S36, Q36)) -> TRUE | Y36: =IF(ISNA(O13), TRUE, ABS($P13-O13) > MAX($S36, R36)) -> TRUE | Z36: =IF(ISNA(M13), TRUE, ABS($P13-M13) > MAX($S36, P36)) -> FALSE | BF36: bom | BG36: collections | BH36: 2
A37: ScalaSQL | B37: asps | C37: avgt | D37: 1 | E37: 5 | F37: 0.043912 | G37: 0.011979 | H37: s/op | J37: Orbits | K37: {=IFERROR(INDEX($Q$3:$Q$18, MATCH(1, ($J37=$L$3:$L$18) * (K$25=$J$3:$J$18), 0)), "")} | L37: {=IFERROR(INDEX($Q$3:$Q$18, MATCH(1, ($J37=$L$3:$L$18) * (L$25=$J$3:$J$18), 0)), "")} -> 3.1664 | M37: {=IFERROR(INDEX($Q$3:$Q$18, MATCH(1, ($J37=$L$3:$L$18) * (M$25=$J$3:$J$18), 0)), "")} | O37: Party | P37: {=INDEX($G$1:$G$100, MATCH(1, ($A$1:$A$100=P$25)*($B$1:$B$100=$K14), 0))} -> 0.008817 | Q37: {=INDEX($G$1:$G$100, MATCH(1, ($A$1:$A$100=Q$25)*($B$1:$B$100=$K14), 0))} -> 0.006658 | R37: {=INDEX($G$1:$G$100, MATCH(1, ($A$1:$A$100=R$25)*($B$1:$B$100=$K14), 0))} -> 0.002275 | S37: {=INDEX($G$1:$G$100, MATCH(1, ($A$1:$A$100=S$25)*($B$1:$B$100=$K14), 0))} -> 0.007748 | T37: =IF(ISNA(N14), TRUE, ABS($M14-N14) > MAX($P37, Q37)) -> TRUE | U37: =IF(ISNA(O14), TRUE, ABS($M14-O14) > MAX($P37, R37)) -> FALSE | V37: =IF(ISNA(P14), TRUE, ABS($M14-P14) > MAX($P37, S37)) -> FALSE | X37: =IF(ISNA(N14), TRUE, ABS($P14-N14) > MAX($S37, Q37)) -> TRUE | Y37: =IF(ISNA(O14), TRUE, ABS($P14-O14) > MAX($S37, R37)) -> FALSE | Z37: =IF(ISNA(M14), TRUE, ABS($P14-M14) > MAX($S37, P37)) -> FALSE | BF37: bom | BG37: collections | BH37: 2
... A41: ScalaSQL | B41: cspa | C41: avgt | D41: 1 | E41: 5 | F41: 0.171146 | G41: 0.023592 | H41: s/op | J41: TC | K41: {=IFERROR(INDEX($Q$3:$Q$18, MATCH(1, ($J41=$L$3:$L$18) * (K$25=$J$3:$J$18), 0)), "")} -> 4.4770776 | L41: {=IFERROR(INDEX($Q$3:$Q$18, MATCH(1, ($J41=$L$3:$L$18) * (L$25=$J$3:$J$18), 0)), "")} | M41: {=IFERROR(INDEX($Q$3:$Q$18, MATCH(1, ($J41=$L$3:$L$18) * (M$25=$J$3:$J$18), 0)), "")} | O41: COT | P41: {=INDEX($G$1:$G$100, MATCH(1, ($A$1:$A$100=P$25)*($B$1:$B$100=$K18), 0))} -> 0.005415 | Q41: {=INDEX($G$1:$G$100, MATCH(1, ($A$1:$A$100=Q$25)*($B$1:$B$100=$K18), 0))} -> 0.019131 | R41: {=INDEX($G$1:$G$100, MATCH(1, ($A$1:$A$100=R$25)*($B$1:$B$100=$K18), 0))} -> 0.001287 | S41: {=INDEX($G$1:$G$100, MATCH(1, ($A$1:$A$100=S$25)*($B$1:$B$100=$K18), 0))} -> 0.003313 | T41: =IF(ISNA(N18), TRUE, ABS($M18-N18) > MAX($P41, Q41)) -> TRUE | U41: =IF(ISNA(O18), TRUE, ABS($M18-O18) > MAX($P41, R41)) -> TRUE | V41: =IF(ISNA(P18), TRUE, ABS($M18-P18) > MAX($P41, S41)) -> FALSE | X41: =IF(ISNA(N18), TRUE, ABS($P18-N18) > MAX($S41, Q41)) -> TRUE | Y41: =IF(ISNA(O18), TRUE, ABS($P18-O18) > MAX($S41, R41)) -> TRUE | Z41: =IF(ISNA(M18), TRUE, ABS($P18-M18) > MAX($S41, P41)) -> FALSE | BF41: cba | BG41: collections | BH41: 9
A42: ScalaSQL | B42: dataflow | C42: avgt | D42: 1 | E42: 5 | F42: 0.047777 | G42: 0.005801 | H42: s/op | BF42: cba | BG42: collections | BH42: 9
A43: ScalaSQL | B43: evenodd | C43: avgt | D43: 1 | E43: 5 | F43: 0.327469 | G43: 0.031792 | H43: s/op | J43: COLLECTIONS | BF43: cba | BG43: collections | BH43: 9
A44: ScalaSQL | B44: javapointsto | C44: avgt | D44: 1 | E44: 5 | F44: 0.076816 | G44: 0.016328 | H44: s/op | J44: Query | K44: Large | L44: Medium | M44: Small | BF44: cba | BG44: collections | BH44: 9
A45: ScalaSQL | B45: orbits | C45: avgt | D45: 1 | E45: 5 | F45: 0.037601 | G45: 0.006033 | H45: s/op | J45: APT | K45: {=IFERROR(INDEX($R$3:$R$18, MATCH(1, ($J45=$L$3:$L$18) * (K$44=$J$3:$J$18), 0)), "")} | L45: {=IFERROR(INDEX($R$3:$R$18, MATCH(1, ($J45=$L$3:$L$18) * (L$44=$J$3:$J$18), 0)), "")} | M45: {=IFERROR(INDEX($R$3:$R$18, MATCH(1, ($J45=$L$3:$L$18) * (M$44=$J$3:$J$18), 0)), "")} -> 0.1131889 | BF45: cba | BG45: collections | BH45: 9
...

Sheet medium
Q1: VS TYQL | T1: VS JDBC_RSQL | AD1: Average of 15 | AE1: Column Labels | AH1: StdDev of Iterations | AI1: Column Labels | BB1: Benchmark | BC1: Mode | BD1: Iterations
A2: Benchmark | B2: Mode | C2: Threads | D2: Samples | E2: Score | F2: Score Error (99.9%) | G2: Unit | J2: Size | K2: Query | L2: Formal Name | M2: TyQL | N2: ScalaSQL | O2: Collections | P2: JDBC_RSQL | Q2: Speedup over Non-Recursive SQL | R2: Speedup over Collections | S2: Speedup over JDBC_RSQL | U2: Speedup over Non-Recursive SQL | V2: Speedup over Collections | W2: Speedup over TyQL | AD2: Row Labels | AE2: collections | AF2: scalasql | AH2: Row Labels | AI2: collections | AJ2: scalasql | BB2: ancestry | BC2: collections | BD2: 15
A3: Collections | B3: ancestry | C3: avgt | D3: 1 | E3: 5 | F3: 3.711833 | G3: 0.249602 | H3: s/op | J3: Large | K3: ancestry | L3: Ancestry | M3: {=INDEX($F$1:$F$100, MATCH(1, (A$1:A$100=M$2)*(B$1:B$100=$K3), 0))} -> 0.209304 | N3: {=INDEX($F$1:$F$100, MATCH(1, (A$1:A$100=N$2)*(B$1:B$100=$K3), 0))} -> 0.422596 | O3: {=INDEX($F$1:$F$100, MATCH(1, (A$1:A$100=O$2)*(B$1:B$100=$K3), 0))} -> 3.711833 | P3: {=INDEX($F$1:$F$100, MATCH(1, (A$1:A$100=P$2)*(B$1:B$100=$K3), 0))} -> 0.213615 | Q3: =IF(ISNA($N3), "DNF", $N3/$M3) -> 2.0190536 | R3: =IF(ISNA(O3), "DNF", O3/$M3) -> 17.734171 | S3: =IF(ISNA($P3), "DNF", $P3/$M3) -> 1.0205968 | U3: =IF(ISNA($N3), "DNF", $N3/$P3) -> 1.9783068 | V3: =IF(ISNA($O3), "DNF", $O3/$P3) -> 17.376275 | W3: =IF(ISNA($M3), "DNF", $M3/$P3) -> 0.97981883 | AD3: ancestry | AE3: 15 | AF3: 15 | AH3: ancestry | AI3: 0 | AJ3: 0 | BB3: ancestry | BC3: collections | BD3: 15
A4: Collections | B4: andersens | C4: avgt | D4: 1 | E4: 5 | F4: 4.858561 | G4: 0.110946 | H4: s/op | J4: Small | K4: andersens | L4: APT | M4: {=INDEX($F$1:$F$100, MATCH(1, (A$1:A$100=M$2)*(B$1:B$100=$K4), 0))} -> 0.020128 | N4: {=INDEX($F$1:$F$100, MATCH(1, (A$1:A$100=N$2)*(B$1:B$100=$K4), 0))} -> 0.086502 | O4: {=INDEX($F$1:$F$100, MATCH(1, (A$1:A$100=O$2)*(B$1:B$100=$K4), 0))} -> 4.858561 | P4: {=INDEX($F$1:$F$100, MATCH(1, (A$1:A$100=P$2)*(B$1:B$100=$K4), 0))} -> 0.016421 | Q4: =IF(ISNA($N4), "DNF", $N4/$M4) -> 4.2975954 | R4: =IF(ISNA(O4), "DNF", O4/$M4) -> 241.3832 | S4: =IF(ISNA($P4), "DNF", $P4/$M4) -> 0.8158287 | U4: =IF(ISNA($N4), "DNF", $N4/$P4) -> 5.2677669 | V4: =IF(ISNA($O4), "DNF", $O4/$P4) -> 295.87486 | W4: =IF(ISNA($M4), "DNF", $M4/$P4) -> 1.2257475 | AD4: andersens | AE4: 9 | AF4: 9 | AH4: andersens | AI4: 0 | AJ4: 0 | BB4: ancestry | BC4: collections | BD4: 15
A5: Collections | B5: asps | C5: avgt | D5: 1 | E5: 5 | F5: 33.197489 | G5: 2.153815 | H5: s/op | J5: Medium | K5: asps | L5: ASPS | M5: {=INDEX($F$1:$F$100, MATCH(1, (A$1:A$100=M$2)*(B$1:B$100=$K5), 0))} -> 0.047768 | N5: {=INDEX($F$1:$F$100, MATCH(1, (A$1:A$100=N$2)*(B$1:B$100=$K5), 0))} -> 0.187528 | O5: {=INDEX($F$1:$F$100, MATCH(1, (A$1:A$100=O$2)*(B$1:B$100=$K5), 0))} -> 33.197489 | P5: {=INDEX($F$1:$F$100, MATCH(1, (A$1:A$100=P$2)*(B$1:B$100=$K5), 0))} -> 0.045341 | Q5: =IF(ISNA($N5), "DNF", $N5/$M5) -> 3.9258081 | R5: =IF(ISNA(O5), "DNF", O5/$M5) -> 694.97339 | S5: =IF(ISNA($P5), "DNF", $P5/$M5) -> 0.94919193 | U5: =IF(ISNA($N5), "DNF", $N5/$P5) -> 4.1359476 | V5: =IF(ISNA($O5), "DNF", $O5/$P5) -> 732.17373 | W5: =IF(ISNA($M5), "DNF", $M5/$P5) -> 1.0535277 | AD5: asps | AE5: 3 | AF5: 3 | AH5: asps | AI5: 0 | AJ5: 0 | BB5: ancestry | BC5: collections | BD5: 15
A6: Collections | B6: bom | C6: avgt | D6: 1 | E6: 5 | F6: 139.44781 | G6: 2.998398 | H6: s/op | J6: Medium | K6: bom | L6: BOM | M6: {=INDEX($F$1:$F$100, MATCH(1, (A$1:A$100=M$2)*(B$1:B$100=$K6), 0))} -> 0.08324 | N6: {=INDEX($F$1:$F$100, MATCH(1, (A$1:A$100=N$2)*(B$1:B$100=$K6), 0))} -> 0.564976 | O6: {=INDEX($F$1:$F$100, MATCH(1, (A$1:A$100=O$2)*(B$1:B$100=$K6), 0))} -> 139.44781 | P6: {=INDEX($F$1:$F$100, MATCH(1, (A$1:A$100=P$2)*(B$1:B$100=$K6), 0))} -> 0.075222 | Q6: =IF(ISNA($N6), "DNF", $N6/$M6) -> 6.7873138 | R6: =IF(ISNA(O6), "DNF", O6/$M6) -> 1675.25 | S6: =IF(ISNA($P6), "DNF", $P6/$M6) -> 0.90367612 | U6: =IF(ISNA($N6), "DNF", $N6/$P6) -> 7.5107814 | V6: =IF(ISNA($O6), "DNF", $O6/$P6) -> 1853.8168 | W6: =IF(ISNA($M6), "DNF", $M6/$P6) -> 1.1065912 | AD6: bom | AE6: 5 | AF6: 5 | AH6: bom | AI6: 0 | AJ6: 0 | BB6: ancestry | BC6: collections | BD6: 15
A7: Collections | B7: cc | C7: avgt | D7: 1 | E7: 5 | F7: 13.838817 | G7: 6.194651 | H7: s/op | J7: Small | K7: cba | L7: CBA | M7: {=INDEX($F$1:$F$100, MATCH(1, (A$1:A$100=M$2)*(B$1:B$100=$K7), 0))} -> 0.01988 | N7: {=INDEX($F$1:$F$100, MATCH(1, (A$1:A$100=N$2)*(B$1:B$100=$K7), 0))} -> 0.054289 | O7: {=INDEX($F$1:$F$100, MATCH(1, (A$1:A$100=O$2)*(B$1:B$100=$K7), 0))} -> #N/A | P7: {=INDEX($F$1:$F$100, MATCH(1, (A$1:A$100=P$2)*(B$1:B$100=$K7), 0))} -> 0.016523 | Q7: =IF(ISNA($N7), "DNF", $N7/$M7) -> 2.730835 | R7: =IF(ISNA(O7), "DNF", O7/$M7) -> DNF | S7: =IF(ISNA($P7), "DNF", $P7/$M7) -> 0.83113682 | U7: =IF(ISNA($N7), "DNF", $N7/$P7) -> 3.2856624 | V7: =IF(ISNA($O7), "DNF", $O7/$P7) -> DNF | W7: =IF(ISNA($M7), "DNF", $M7/$P7) -> 1.2031713 | AD7: cba | AF7: 1 | AH7: cba | AJ7: 0 | BB7: ancestry | BC7: collections | BD7: 15
A8: Collections | B8: dataflow | C8: avgt | D8: 1 | E8: 5 | F8: 17.674676 | G8: 0.235394 | H8: s/op | J8: Medium | K8: cc | L8: CC | M8: {=INDEX($F$1:$F$100, MATCH(1, (A$1:A$100=M$2)*(B$1:B$100=$K8), 0))} -> 0.295005 | N8: {=INDEX($F$1:$F$100, MATCH(1, (A$1:A$100=N$2)*(B$1:B$100=$K8), 0))} -> 0.7659 | O8: {=INDEX($F$1:$F$100, MATCH(1, (A$1:A$100=O$2)*(B$1:B$100=$K8), 0))} -> 13.838817 | P8: {=INDEX($F$1:$F$100, MATCH(1, (A$1:A$100=P$2)*(B$1:B$100=$K8), 0))} -> 0.299997 | Q8: =IF(ISNA($N8), "DNF", $N8/$M8) -> 2.5962272 | R8: =IF(ISNA(O8), "DNF", O8/$M8) -> 46.910449 | S8: =IF(ISNA($P8), "DNF", $P8/$M8) -> 1.0169217 | U8: =IF(ISNA($N8), "DNF", $N8/$P8) -> 2.5530255 | V8: =IF(ISNA($O8), "DNF", $O8/$P8) -> 46.129851 | W8: =IF(ISNA($M8), "DNF", $M8/$P8) -> 0.98335983 | AD8: cc | AE8: 3 | AF8: 3 | AH8: cc | AI8: 0 | AJ8: 0 | BB8: ancestry | BC8: collections | BD8: 15
A9: Collections | B9: sssp | C9: avgt | D9: 1 | E9: 5 | F9: 0.578081 | G9: 0.101012 | H9: s/op | J9: Medium | K9: cspa | L9: CSPA | M9: {=INDEX($F$1:$F$100, MATCH(1, (A$1:A$100=M$2)*(B$1:B$100=$K9), 0))} -> 1.06881 | N9: {=INDEX($F$1:$F$100, MATCH(1, (A$1:A$100=N$2)*(B$1:B$100=$K9), 0))} -> 5.711531 | O9: {=INDEX($F$1:$F$100, MATCH(1, (A$1:A$100=O$2)*(B$1:B$100=$K9), 0))} -> #N/A | P9: {=INDEX($F$1:$F$100, MATCH(1, (A$1:A$100=P$2)*(B$1:B$100=$K9), 0))} -> 1.109318 | Q9: =IF(ISNA($N9), "DNF", $N9/$M9) -> 5.3438226 | R9: =IF(ISNA(O9), "DNF", O9/$M9) -> DNF | S9: =IF(ISNA($P9), "DNF", $P9/$M9) -> 1.0379001 | U9: =IF(ISNA($N9), "DNF", $N9/$P9) -> 5.1486869 | V9: =IF(ISNA($O9), "DNF", $O9/$P9) -> DNF | W9: =IF(ISNA($M9), "DNF", $M9/$P9) -> 0.96348387 | AD9: cspa | AF9: 11 | AH9: cspa | AJ9: 0 | BB9: ancestry | BC9: collections | BD9: 15
A10: Collections | B10: tc | C10: avgt | D10: 1 | E10: 5 | F10: 0.332675 | G10: 0.014732 | H10: s/op | J10: Small | K10: dataflow | L10: Data Flow | M10: {=INDEX($F$1:$F$100, MATCH(1, (A$1:A$100=M$2)*(B$1:B$100=$K10), 0))} -> 0.009992 | N10: {=INDEX($F$1:$F$100, MATCH(1, (A$1:A$100=N$2)*(B$1:B$100=$K10), 0))} -> 0.058332 | O10: {=INDEX($F$1:$F$100, MATCH(1, (A$1:A$100=O$2)*(B$1:B$100=$K10), 0))} -> 17.674676 | P10: {=INDEX($F$1:$F$100, MATCH(1, (A$1:A$100=P$2)*(B$1:B$100=$K10), 0))} -> 0.008356 | Q10: =IF(ISNA($N10), "DNF", $N10/$M10) -> 5.8378703 | R10: =IF(ISNA(O10), "DNF", O10/$M10) -> 1768.8827 | S10: =IF(ISNA($P10), "DNF", $P10/$M10) -> 0.83626902 | U10: =IF(ISNA($N10), "DNF", $N10/$P10) -> 6.9808521 | V10: =IF(ISNA($O10), "DNF", $O10/$P10) -> 2115.2078 | W10: =IF(ISNA($M10), "DNF", $M10/$P10) -> 1.1957875 | AD10: dataflow | AE10: 5 | AF10: 5 | AH10: dataflow | AI10: 0 | AJ10: 0 | BB10: ancestry | BC10: collections | BD10: 15
A11: JDBC_RSQL | B11: ancestry | C11: avgt | D11: 1 | E11: 5 | F11: 0.213615 | G11: 0.032332 | H11: s/op | J11: Medium | K11: evenodd | L11: Even-Odd | M11: {=INDEX($F$1:$F$100, MATCH(1, (A$1:A$100=M$2)*(B$1:B$100=$K11), 0))} -> 181.48792 | N11: {=INDEX($F$1:$F$100, MATCH(1, (A$1:A$100=N$2)*(B$1:B$100=$K11), 0))} -> #N/A | O11: {=INDEX($F$1:$F$100, MATCH(1, (A$1:A$100=O$2)*(B$1:B$100=$K11), 0))} -> #N/A | P11: {=INDEX($F$1:$F$100, MATCH(1, (A$1:A$100=P$2)*(B$1:B$100=$K11), 0))} -> 178.27417 | Q11: =IF(ISNA($N11), "DNF", $N11/$M11) -> DNF | R11: =IF(ISNA(O11), "DNF", O11/$M11) -> DNF | S11: =IF(ISNA($P11), "DNF", $P11/$M11) -> 0.98229222 | U11: =IF(ISNA($N11), "DNF", $N11/$P11) -> DNF | V11: =IF(ISNA($O11), "DNF", $O11/$P11) -> DNF | W11: =IF(ISNA($M11), "DNF", $M11/$P11) -> 1.018027 | AD11: javapointsto | AF11: 16 | AH11: javapointsto | AJ11: 0 | BB11: ancestry | BC11: collections | BD11: 15
A12: JDBC_RSQL | B12: andersens | C12: avgt | D12: 1 | E12: 5 | F12: 0.016421 | G12: 0.007981 | H12: s/op | J12: Small | K12: javapointsto | L12: JPT | M12: {=INDEX($F$1:$F$100, MATCH(1, (A$1:A$100=M$2)*(B$1:B$100=$K12), 0))} -> 0.054668 | N12: {=INDEX($F$1:$F$100, MATCH(1, (A$1:A$100=N$2)*(B$1:B$100=$K12), 0))} -> 0.834537 | O12: {=INDEX($F$1:$F$100, MATCH(1, (A$1:A$100=O$2)*(B$1:B$100=$K12), 0))} -> #N/A | P12: {=INDEX($F$1:$F$100, MATCH(1, (A$1:A$100=P$2)*(B$1:B$100=$K12), 0))} -> 0.052683 | Q12: =IF(ISNA($N12), "DNF", $N12/$M12) -> 15.265548 | R12: =IF(ISNA(O12), "DNF", O12/$M12) -> DNF | S12: =IF(ISNA($P12), "DNF", $P12/$M12) -> 0.96368991 | U12: =IF(ISNA($N12), "DNF", $N12/$P12) -> 15.840727 | V12: =IF(ISNA($O12), "DNF", $O12/$P12) -> DNF | W12: =IF(ISNA($M12), "DNF", $M12/$P12) -> 1.0376782 | AD12: orbits | AF12: 2 | AH12: orbits | AJ12: 0 | BB12: andersens | BC12: collections | BD12: 4
A13: JDBC_RSQL | B13: asps | C13: avgt | D13: 1 | E13: 5 | F13: 0.045341 | G13: 0.014982 | H13: s/op | J13: Medium | K13: orbits | L13: Orbits | M13: {=INDEX($F$1:$F$100, MATCH(1, (A$1:A$100=M$2)*(B$1:B$100=$K13), 0))} -> 0.076638 | N13: {=INDEX($F$1:$F$100, MATCH(1, (A$1:A$100=N$2)*(B$1:B$100=$K13), 0))} -> 0.391855 | O13: {=INDEX($F$1:$F$100, MATCH(1, (A$1:A$100=O$2)*(B$1:B$100=$K13), 0))} -> #N/A | P13: {=INDEX($F$1:$F$100, MATCH(1, (A$1:A$100=P$2)*(B$1:B$100=$K13), 0))} -> 0.074972 | Q13: =IF(ISNA($N13), "DNF", $N13/$M13) -> 5.113064 | R13: =IF(ISNA(O13), "DNF", O13/$M13) -> DNF | S13: =IF(ISNA($P13), "DNF", $P13/$M13) -> 0.97826144 | U13: =IF(ISNA($N13), "DNF", $N13/$P13) -> 5.2266846 | V13: =IF(ISNA($O13), "DNF", $O13/$P13) -> DNF | W13: =IF(ISNA($M13), "DNF", $M13/$P13) -> 1.0222216 | AD13: party | AF13: 5 | AH13: party | AJ13: 0 | BB13: andersens | BC13: collections | BD13: 4
A14: JDBC_RSQL | B14: bom | C14: avgt | D14: 1 | E14: 5 | F14: 0.075222 | G14: 0.020248 | H14: s/op | J14: Medium | K14: party | L14: Party | M14: {=INDEX($F$1:$F$100, MATCH(1, (A$1:A$100=M$2)*(B$1:B$100=$K14), 0))} -> 0.093256 | N14: {=INDEX($F$1:$F$100, MATCH(1, (A$1:A$100=N$2)*(B$1:B$100=$K14), 0))} -> 0.953685 | O14: {=INDEX($F$1:$F$100, MATCH(1, (A$1:A$100=O$2)*(B$1:B$100=$K14), 0))} -> #N/A | P14: {=INDEX($F$1:$F$100, MATCH(1, (A$1:A$100=P$2)*(B$1:B$100=$K14), 0))} -> 0.08861 | Q14: =IF(ISNA($N14), "DNF", $N14/$M14) -> 10.226527 | R14: =IF(ISNA(O14), "DNF", O14/$M14) -> DNF | S14: =IF(ISNA($P14), "DNF", $P14/$M14) -> 0.95018015 | U14: =IF(ISNA($N14), "DNF", $N14/$P14) -> 10.762724 | V14: =IF(ISNA($O14), "DNF", $O14/$P14) -> DNF | W14: =IF(ISNA($M14), "DNF", $M14/$P14) -> 1.052432 | AD14: pointstocount | AF14: 16 | AH14: pointstocount | AJ14: 0 | BB14: andersens | BC14: collections | BD14: 4
A15: JDBC_RSQL | B15: cba | C15: avgt | D15: 1 | E15: 5 | F15: 0.016523 | G15: 0.005561 | H15: s/op | J15: Small | K15: pointstocount | L15: PTC | M15: {=INDEX($F$1:$F$100, MATCH(1, (A$1:A$100=M$2)*(B$1:B$100=$K15), 0))} -> 0.052132 | N15: {=INDEX($F$1:$F$100, MATCH(1, (A$1:A$100=N$2)*(B$1:B$100=$K15), 0))} -> 0.840979 | O15: {=INDEX($F$1:$F$100, MATCH(1, (A$1:A$100=O$2)*(B$1:B$100=$K15), 0))} -> #N/A | P15: {=INDEX($F$1:$F$100, MATCH(1, (A$1:A$100=P$2)*(B$1:B$100=$K15), 0))} -> 0.047639 | Q15: =IF(ISNA($N15), "DNF", $N15/$M15) -> 16.131723 | R15: =IF(ISNA(O15), "DNF", O15/$M15) -> DNF | S15: =IF(ISNA($P15), "DNF", $P15/$M15) -> 0.91381493 | U15: =IF(ISNA($N15), "DNF", $N15/$P15) -> 17.653162 | V15: =IF(ISNA($O15), "DNF", $O15/$P15) -> DNF | W15: =IF(ISNA($M15), "DNF", $M15/$P15) -> 1.0943135 | AD15: sssp | AE15: 9 | AF15: 9 | AH15: sssp | AI15: 0 | AJ15: 0 | BB15: andersens | BC15: collections | BD15: 4
A16: JDBC_RSQL | B16: cc | C16: avgt | D16: 1 | E16: 5 | F16: 0.299997 | G16: 0.015205 | H16: s/op | J16: Large | K16: sssp | L16: SSSP | M16: {=INDEX($F$1:$F$100, MATCH(1, (A$1:A$100=M$2)*(B$1:B$100=$K16), 0))} -> 0.026469 | N16: {=INDEX($F$1:$F$100, MATCH(1, (A$1:A$100=N$2)*(B$1:B$100=$K16), 0))} -> 0.152309 | O16: {=INDEX($F$1:$F$100, MATCH(1, (A$1:A$100=O$2)*(B$1:B$100=$K16), 0))} -> 0.578081 | P16: {=INDEX($F$1:$F$100, MATCH(1, (A$1:A$100=P$2)*(B$1:B$100=$K16), 0))} -> 0.025665 | Q16: =IF(ISNA($N16), "DNF", $N16/$M16) -> 5.7542408 | R16: =IF(ISNA(O16), "DNF", O16/$M16) -> 21.839926 | S16: =IF(ISNA($P16), "DNF", $P16/$M16) -> 0.96962484 | U16: =IF(ISNA($N16), "DNF", $N16/$P16) -> 5.9345022 | V16: =IF(ISNA($O16), "DNF", $O16/$P16) -> 22.524099 | W16: =IF(ISNA($M16), "DNF", $M16/$P16) -> 1.0313267 | AD16: tc | AE16: 5 | AF16: 5 | AH16: tc | AI16: 0 | AJ16: 0 | BB16: andersens | BC16: collections | BD16: 4
A17: JDBC_RSQL | B17: cspa | C17: avgt | D17: 1 | E17: 5 | F17: 1.109318 | G17: 0.1164 | H17: s/op | J17: Large | K17: tc | L17: TC | M17: {=INDEX($F$1:$F$100, MATCH(1, (A$1:A$100=M$2)*(B$1:B$100=$K17), 0))} -> 0.020929 | N17: {=INDEX($F$1:$F$100, MATCH(1, (A$1:A$100=N$2)*(B$1:B$100=$K17), 0))} -> 0.079343 | O17: {=INDEX($F$1:$F$100, MATCH(1, (A$1:A$100=O$2)*(B$1:B$100=$K17), 0))} -> 0.332675 | P17: {=INDEX($F$1:$F$100, MATCH(1, (A$1:A$100=P$2)*(B$1:B$100=$K17), 0))} -> 0.017424 | Q17: =IF(ISNA($N17), "DNF", $N17/$M17) -> 3.7910555 | R17: =IF(ISNA(O17), "DNF", O17/$M17) -> 15.895408 | S17: =IF(ISNA($P17), "DNF", $P17/$M17) -> 0.83252903 | U17: =IF(ISNA($N17), "DNF", $N17/$P17) -> 4.5536616 | V17: =IF(ISNA($O17), "DNF", $O17/$P17) -> 19.092918 | W17: =IF(ISNA($M17), "DNF", $M17/$P17) -> 1.2011593 | AD17: trustchain | AF17: 7 | AH17: trustchain | AJ17: 0 | BB17: andersens | BC17: collections | BD17: 4
A18: JDBC_RSQL | B18: dataflow | C18: avgt | D18: 1 | E18: 5 | F18: 0.008356 | G18: 0.005042 | H18: s/op | J18: Medium | K18: trustchain | L18: COT | M18: {=INDEX($F$1:$F$100, MATCH(1, (A$1:A$100=M$2)*(B$1:B$100=$K18), 0))} -> 0.124113 | N18: {=INDEX($F$1:$F$100, MATCH(1, (A$1:A$100=N$2)*(B$1:B$100=$K18), 0))} -> 2.610661 | O18: {=INDEX($F$1:$F$100, MATCH(1, (A$1:A$100=O$2)*(B$1:B$100=$K18), 0))} -> #N/A | P18: {=INDEX($F$1:$F$100, MATCH(1, (A$1:A$100=P$2)*(B$1:B$100=$K18), 0))} -> 0.123728 | Q18: =IF(ISNA($N18), "DNF", $N18/$M18) -> 21.034549 | R18: =IF(ISNA(O18), "DNF", O18/$M18) -> DNF | S18: =IF(ISNA($P18), "DNF", $P18/$M18) -> 0.99689799 | U18: =IF(ISNA($N18), "DNF", $N18/$P18) -> 21.100002 | V18: =IF(ISNA($O18), "DNF", $O18/$P18) -> DNF | W18: =IF(ISNA($M18), "DNF", $M18/$P18) -> 1.0031117 | BB18: andersens | BC18: collections | BD18: 4
A19: JDBC_RSQL | B19: evenodd | C19: avgt | D19: 1 | E19: 5 | F19: 178.27417 | G19: 7.189667 | H19: s/op | BB19: andersens | BC19: collections | BD19: 4
A20: JDBC_RSQL | B20: javapointsto | C20: avgt | D20: 1 | E20: 5 | F20: 0.052683 | G20: 0.009181 | H20: s/op | BB20: andersens | BC20: collections | BD20: 4
A21: JDBC_RSQL | B21: orbits | C21: avgt | D21: 1 | E21: 5 | F21: 0.074972 | G21: 0.014523 | H21: s/op | BB21: andersens | BC21: collections | BD21: 4
A22: JDBC_RSQL | B22: party | C22: avgt | D22: 1 | E22: 5 | F22: 0.08861 | G22: 0.014751 | H22: s/op | BB22: asps | BC22: collections | BD22: 3
A23: JDBC_RSQL | B23: pointstocount | C23: avgt | D23: 1 | E23: 5 | F23: 0.047639 | G23: 0.008205 | H23: s/op | BB23: asps | BC23: collections | BD23: 3
A24: JDBC_RSQL | B24: sssp | C24: avgt | D24: 1 | E24: 5 | F24: 0.025665 | G24: 0.006957 | H24: s/op | J24: SCALASQL | P24: Margin of Error: | T24: TyQL Speedup exceeds error margin? | X24: JDBC_RSQL Speedup exceeds error margin? | BB24: asps | BC24: collections | BD24: 3
A25: JDBC_RSQL | B25: tc | C25: avgt | D25: 1 | E25: 5 | F25: 0.017424 | G25: 0.007413 | H25: s/op | J25: Query | K25: Large | L25: Medium | M25: Small | O25: Formal Name | P25: TyQL | Q25: ScalaSQL | R25: Collections | S25: JDBC_RSQL | T25: SCALASQL | U25: COLLECTIONS | V25: JDBC_RSQL | X25: SCALASQL | Y25: COLLECTIONS | Z25: TyQL | BB25: asps | BC25: collections | BD25: 3
A26: JDBC_RSQL | B26: trustchain | C26: avgt | D26: 1 | E26: 5 | F26: 0.123728 | G26: 0.011287 | H26: s/op | J26: APT | K26: {=IFERROR(INDEX($Q$3:$Q$18, MATCH(1, ($J26=$L$3:$L$18) * (K$25=$J$3:$J$18), 0)), "")} | L26: {=IFERROR(INDEX($Q$3:$Q$18, MATCH(1, ($J26=$L$3:$L$18) * (L$25=$J$3:$J$18), 0)), "")} | M26: {=IFERROR(INDEX($Q$3:$Q$18, MATCH(1, ($J26=$L$3:$L$18) * (M$25=$J$3:$J$18), 0)), "")} -> 4.2975954 | O26: Ancestry | P26: {=INDEX($G$1:$G$100, MATCH(1, ($A$1:$A$100=P$25)*($B$1:$B$100=$K3), 0))} -> 0.059806 | Q26: {=INDEX($G$1:$G$100, MATCH(1, ($A$1:$A$100=Q$25)*($B$1:$B$100=$K3), 0))} -> 0.034178 | R26: {=INDEX($G$1:$G$100, MATCH(1, ($A$1:$A$100=R$25)*($B$1:$B$100=$K3), 0))} -> 0.249602 | S26: {=INDEX($G$1:$G$100, MATCH(1, ($A$1:$A$100=S$25)*($B$1:$B$100=$K3), 0))} -> 0.032332 | T26: =IF(ISNA(N3), TRUE, ABS($M3-N3) > MAX($P26, Q26)) -> TRUE | U26: =IF(ISNA(O3), TRUE, ABS($M3-O3) > MAX($P26, R26)) -> TRUE | V26: =IF(ISNA(P3), TRUE, ABS($M3-P3) > MAX($P26, S26)) -> FALSE | X26: =IF(ISNA(N3), TRUE, ABS($P3-N3) > MAX($S26, Q26)) -> TRUE | Y26: =IF(ISNA(O3), TRUE, ABS($P3-O3) > MAX($S26, R26)) -> TRUE | Z26: =IF(ISNA(M3), TRUE, ABS($P3-M3) > MAX($S26, P26)) -> FALSE | BB26: asps | BC26: collections | BD26: 3
A27: ScalaSQL | B27: ancestry | C27: avgt | D27: 1 | E27: 5 | F27: 0.422596 | G27: 0.034178 | H27: s/op | J27: CBA | K27: {=IFERROR(INDEX($Q$3:$Q$18, MATCH(1, ($J27=$L$3:$L$18) * (K$25=$J$3:$J$18), 0)), "")} | L27: {=IFERROR(INDEX($Q$3:$Q$18, MATCH(1, ($J27=$L$3:$L$18) * (L$25=$J$3:$J$18), 0)), "")} | M27: {=IFERROR(INDEX($Q$3:$Q$18, MATCH(1, ($J27=$L$3:$L$18) * (M$25=$J$3:$J$18), 0)), "")} -> 2.730835 | O27: APT | P27: {=INDEX($G$1:$G$100, MATCH(1, ($A$1:$A$100=P$25)*($B$1:$B$100=$K4), 0))} -> 0.010291 | Q27: {=INDEX($G$1:$G$100, MATCH(1, ($A$1:$A$100=Q$25)*($B$1:$B$100=$K4), 0))} -> 0.013379 | R27: {=INDEX($G$1:$G$100, MATCH(1, ($A$1:$A$100=R$25)*($B$1:$B$100=$K4), 0))} -> 0.110946 | S27: {=INDEX($G$1:$G$100, MATCH(1, ($A$1:$A$100=S$25)*($B$1:$B$100=$K4), 0))} -> 0.007981 | T27: =IF(ISNA(N4), TRUE, ABS($M4-N4) > MAX($P27, Q27)) -> TRUE | U27: =IF(ISNA(O4), TRUE, ABS($M4-O4) > MAX($P27, R27)) -> TRUE | V27: =IF(ISNA(P4), TRUE, ABS($M4-P4) > MAX($P27, S27)) -> FALSE | X27: =IF(ISNA(N4), TRUE, ABS($P4-N4) > MAX($S27, Q27)) -> TRUE | Y27: =IF(ISNA(O4), TRUE, ABS($P4-O4) > MAX($S27, R27)) -> TRUE | Z27: =IF(ISNA(M4), TRUE, ABS($P4-M4) > MAX($S27, P27)) -> FALSE | BB27: asps | BC27: collections | BD27: 3
A28: ScalaSQL | B28: andersens | C28: avgt | D28: 1 | E28: 5 | F28: 0.086502 | G28: 0.013379 | H28: s/op | J28: Data Flow | K28: {=IFERROR(INDEX($Q$3:$Q$18, MATCH(1, ($J28=$L$3:$L$18) * (K$25=$J$3:$J$18), 0)), "")} | L28: {=IFERROR(INDEX($Q$3:$Q$18, MATCH(1, ($J28=$L$3:$L$18) * (L$25=$J$3:$J$18), 0)), "")} | M28: {=IFERROR(INDEX($Q$3:$Q$18, MATCH(1, ($J28=$L$3:$L$18) * (M$25=$J$3:$J$18), 0)), "")} -> 5.8378703 | O28: ASPS | P28: {=INDEX($G$1:$G$100, MATCH(1, ($A$1:$A$100=P$25)*($B$1:$B$100=$K5), 0))} -> 0.004074 | Q28: {=INDEX($G$1:$G$100, MATCH(1, ($A$1:$A$100=Q$25)*($B$1:$B$100=$K5), 0))} -> 0.014536 | R28: {=INDEX($G$1:$G$100, MATCH(1, ($A$1:$A$100=R$25)*($B$1:$B$100=$K5), 0))} -> 2.153815 | S28: {=INDEX($G$1:$G$100, MATCH(1, ($A$1:$A$100=S$25)*($B$1:$B$100=$K5), 0))} -> 0.014982 | T28: =IF(ISNA(N5), TRUE, ABS($M5-N5) > MAX($P28, Q28)) -> TRUE | U28: =IF(ISNA(O5), TRUE, ABS($M5-O5) > MAX($P28, R28)) -> TRUE | V28: =IF(ISNA(P5), TRUE, ABS($M5-P5) > MAX($P28, S28)) -> FALSE | X28: =IF(ISNA(N5), TRUE, ABS($P5-N5) > MAX($S28, Q28)) -> TRUE | Y28: =IF(ISNA(O5), TRUE, ABS($P5-O5) > MAX($S28, R28)) -> TRUE | Z28: =IF(ISNA(M5), TRUE, ABS($P5-M5) > MAX($S28, P28)) -> FALSE | BB28: asps | BC28: collections | BD28: 3
A29: ScalaSQL | B29: asps | C29: avgt | D29: 1 | E29: 5 | F29: 0.187528 | G29: 0.014536 | H29: s/op | J29: JPT | K29: {=IFERROR(INDEX($Q$3:$Q$18, MATCH(1, ($J29=$L$3:$L$18) * (K$25=$J$3:$J$18), 0)), "")} | L29: {=IFERROR(INDEX($Q$3:$Q$18, MATCH(1, ($J29=$L$3:$L$18) * (L$25=$J$3:$J$18), 0)), "")} | M29: {=IFERROR(INDEX($Q$3:$Q$18, MATCH(1, ($J29=$L$3:$L$18) * (M$25=$J$3:$J$18), 0)), "")} -> 15.265548 | O29: BOM | P29: {=INDEX($G$1:$G$100, MATCH(1, ($A$1:$A$100=P$25)*($B$1:$B$100=$K6), 0))} -> 0.028547 | Q29: {=INDEX($G$1:$G$100, MATCH(1, ($A$1:$A$100=Q$25)*($B$1:$B$100=$K6), 0))} -> 0.017455 | R29: {=INDEX($G$1:$G$100, MATCH(1, ($A$1:$A$100=R$25)*($B$1:$B$100=$K6), 0))} -> 2.998398 | S29: {=INDEX($G$1:$G$100, MATCH(1, ($A$1:$A$100=S$25)*($B$1:$B$100=$K6), 0))} -> 0.020248 | T29: =IF(ISNA(N6), TRUE, ABS($M6-N6) > MAX($P29, Q29)) -> TRUE | U29: =IF(ISNA(O6), TRUE, ABS($M6-O6) > MAX($P29, R29)) -> TRUE | V29: =IF(ISNA(P6), TRUE, ABS($M6-P6) > MAX($P29, S29)) -> FALSE | X29: =IF(ISNA(N6), TRUE, ABS($P6-N6) > MAX($S29, Q29)) -> TRUE | Y29: =IF(ISNA(O6), TRUE, ABS($P6-O6) > MAX($S29, R29)) -> TRUE | Z29: =IF(ISNA(M6), TRUE, ABS($P6-M6) > MAX($S29, P29)) -> FALSE | BB29: asps | BC29: collections | BD29: 3
A30: ScalaSQL | B30: bom | C30: avgt | D30: 1 | E30: 5 | F30: 0.564976 | G30: 0.017455 | H30: s/op | J30: PTC | K30: {=IFERROR(INDEX($Q$3:$Q$18, MATCH(1, ($J30=$L$3:$L$18) * (K$25=$J$3:$J$18), 0)), "")} | L30: {=IFERROR(INDEX($Q$3:$Q$18, MATCH(1, ($J30=$L$3:$L$18) * (L$25=$J$3:$J$18), 0)), "")} | M30: {=IFERROR(INDEX($Q$3:$Q$18, MATCH(1, ($J30=$L$3:$L$18) * (M$25=$J$3:$J$18), 0)), "")} -> 16.131723 | O30: CBA | P30: {=INDEX($G$1:$G$100, MATCH(1, ($A$1:$A$100=P$25)*($B$1:$B$100=$K7), 0))} -> 0.013756 | Q30: {=INDEX($G$1:$G$100, MATCH(1, ($A$1:$A$100=Q$25)*($B$1:$B$100=$K7), 0))} -> 0.005301 | R30: {=INDEX($G$1:$G$100, MATCH(1, ($A$1:$A$100=R$25)*($B$1:$B$100=$K7), 0))} -> #N/A | S30: {=INDEX($G$1:$G$100, MATCH(1, ($A$1:$A$100=S$25)*($B$1:$B$100=$K7), 0))} -> 0.005561 | T30: =IF(ISNA(N7), TRUE, ABS($M7-N7) > MAX($P30, Q30)) -> TRUE | U30: =IF(ISNA(O7), TRUE, ABS($M7-O7) > MAX($P30, R30)) -> TRUE | V30: =IF(ISNA(P7), TRUE, ABS($M7-P7) > MAX($P30, S30)) -> FALSE | X30: =IF(ISNA(N7), TRUE, ABS($P7-N7) > MAX($S30, Q30)) -> TRUE | Y30: =IF(ISNA(O7), TRUE, ABS($P7-O7) > MAX($S30, R30)) -> TRUE | Z30: =IF(ISNA(M7), TRUE, ABS($P7-M7) > MAX($S30, P30)) -> FALSE | BB30: asps | BC30: collections | BD30: 3
A31: ScalaSQL | B31: cba | C31: avgt | D31: 1 | E31: 5 | F31: 0.054289 | G31: 0.005301 | H31: s/op | J31: ASPS | K31: {=IFERROR(INDEX($Q$3:$Q$18, MATCH(1, ($J31=$L$3:$L$18) * (K$25=$J$3:$J$18), 0)), "")} | L31: {=IFERROR(INDEX($Q$3:$Q$18, MATCH(1, ($J31=$L$3:$L$18) * (L$25=$J$3:$J$18), 0)), "")} -> 3.9258081 | M31: {=IFERROR(INDEX($Q$3:$Q$18, MATCH(1, ($J31=$L$3:$L$18) * (M$25=$J$3:$J$18), 0)), "")} | O31: CC | P31: {=INDEX($G$1:$G$100, MATCH(1, ($A$1:$A$100=P$25)*($B$1:$B$100=$K8), 0))} -> 0.030958 | Q31: {=INDEX($G$1:$G$100, MATCH(1, ($A$1:$A$100=Q$25)*($B$1:$B$100=$K8), 0))} -> 0.046832 | R31: {=INDEX($G$1:$G$100, MATCH(1, ($A$1:$A$100=R$25)*($B$1:$B$100=$K8), 0))} -> 6.194651 | S31: {=INDEX($G$1:$G$100, MATCH(1, ($A$1:$A$100=S$25)*($B$1:$B$100=$K8), 0))} -> 0.015205 | T31: =IF(ISNA(N8), TRUE, ABS($M8-N8) > MAX($P31, Q31)) -> TRUE | U31: =IF(ISNA(O8), TRUE, ABS($M8-O8) > MAX($P31, R31)) -> TRUE | V31: =IF(ISNA(P8), TRUE, ABS($M8-P8) > MAX($P31, S31)) -> FALSE | X31: =IF(ISNA(N8), TRUE, ABS($P8-N8) > MAX($S31, Q31)) -> TRUE | Y31: =IF(ISNA(O8), TRUE, ABS($P8-O8) > MAX($S31, R31)) -> TRUE | Z31: =IF(ISNA(M8), TRUE, ABS($P8-M8) > MAX($S31, P31)) -> FALSE | BB31: asps | BC31: collections | BD31: 3
A32: ScalaSQL | B32: cc | C32: avgt | D32: 1 | E32: 5 | F32: 0.7659 | G32: 0.046832 | H32: s/op | J32: BOM | K32: {=IFERROR(INDEX($Q$3:$Q$18, MATCH(1, ($J32=$L$3:$L$18) * (K$25=$J$3:$J$18), 0)), "")} | L32: {=IFERROR(INDEX($Q$3:$Q$18, MATCH(1, ($J32=$L$3:$L$18) * (L$25=$J$3:$J$18), 0)), "")} -> 6.7873138 | M32: {=IFERROR(INDEX($Q$3:$Q$18, MATCH(1, ($J32=$L$3:$L$18) * (M$25=$J$3:$J$18), 0)), "")} | O32: CSPA | P32: {=INDEX($G$1:$G$100, MATCH(1, ($A$1:$A$100=P$25)*($B$1:$B$100=$K9), 0))} -> 0.105325 | Q32: {=INDEX($G$1:$G$100, MATCH(1, ($A$1:$A$100=Q$25)*($B$1:$B$100=$K9), 0))} -> 0.334228 | R32: {=INDEX($G$1:$G$100, MATCH(1, ($A$1:$A$100=R$25)*($B$1:$B$100=$K9), 0))} -> #N/A | S32: {=INDEX($G$1:$G$100, MATCH(1, ($A$1:$A$100=S$25)*($B$1:$B$100=$K9), 0))} -> 0.1164 | T32: =IF(ISNA(N9), TRUE, ABS($M9-N9) > MAX($P32, Q32)) -> TRUE | U32: =IF(ISNA(O9), TRUE, ABS($M9-O9) > MAX($P32, R32)) -> TRUE | V32: =IF(ISNA(P9), TRUE, ABS($M9-P9) > MAX($P32, S32)) -> FALSE | X32: =IF(ISNA(N9), TRUE, ABS($P9-N9) > MAX($S32, Q32)) -> TRUE | Y32: =IF(ISNA(O9), TRUE, ABS($P9-O9) > MAX($S32, R32)) -> TRUE | Z32: =IF(ISNA(M9), TRUE, ABS($P9-M9) > MAX($S32, P32)) -> FALSE | BB32: bom | BC32: collections | BD32: 5
A33: ScalaSQL | B33: cspa | C33: avgt | D33: 1 | E33: 5 | F33: 5.711531 | G33: 0.334228 | H33: s/op | J33: CC | K33: {=IFERROR(INDEX($Q$3:$Q$18, MATCH(1, ($J33=$L$3:$L$18) * (K$25=$J$3:$J$18), 0)), "")} | L33: {=IFERROR(INDEX($Q$3:$Q$18, MATCH(1, ($J33=$L$3:$L$18) * (L$25=$J$3:$J$18), 0)), "")} -> 2.5962272 | M33: {=IFERROR(INDEX($Q$3:$Q$18, MATCH(1, ($J33=$L$3:$L$18) * (M$25=$J$3:$J$18), 0)), "")} | O33: Data Flow | P33: {=INDEX($G$1:$G$100, MATCH(1, ($A$1:$A$100=P$25)*($B$1:$B$100=$K10), 0))} -> 0.007308 | Q33: {=INDEX($G$1:$G$100, MATCH(1, ($A$1:$A$100=Q$25)*($B$1:$B$100=$K10), 0))} -> 0.015427 | R33: {=INDEX($G$1:$G$100, MATCH(1, ($A$1:$A$100=R$25)*($B$1:$B$100=$K10), 0))} -> 0.235394 | S33: {=INDEX($G$1:$G$100, MATCH(1, ($A$1:$A$100=S$25)*($B$1:$B$100=$K10), 0))} -> 0.005042 | T33: =IF(ISNA(N10), TRUE, ABS($M10-N10) > MAX($P33, Q33)) -> TRUE | U33: =IF(ISNA(O10), TRUE, ABS($M10-O10) > MAX($P33, R33)) -> TRUE | V33: =IF(ISNA(P10), TRUE, ABS($M10-P10) > MAX($P33, S33)) -> FALSE | X33: =IF(ISNA(N10), TRUE, ABS($P10-N10) > MAX($S33, Q33)) -> TRUE | Y33: =IF(ISNA(O10), TRUE, ABS($P10-O10) > MAX($S33, R33)) -> TRUE | Z33: =IF(ISNA(M10), TRUE, ABS($P10-M10) > MAX($S33, P33)) -> FALSE | BB33: bom | BC33: collections | BD33: 5
A34: ScalaSQL | B34: dataflow | C34: avgt | D34: 1 | E34: 5 | F34: 0.058332 | G34: 0.015427 | H34: s/op | J34: COT | K34: {=IFERROR(INDEX($Q$3:$Q$18, MATCH(1, ($J34=$L$3:$L$18) * (K$25=$J$3:$J$18), 0)), "")} | L34: {=IFERROR(INDEX($Q$3:$Q$18, MATCH(1, ($J34=$L$3:$L$18) * (L$25=$J$3:$J$18), 0)), "")} -> 21.034549 | M34: {=IFERROR(INDEX($Q$3:$Q$18, MATCH(1, ($J34=$L$3:$L$18) * (M$25=$J$3:$J$18), 0)), "")} | O34: Even-Odd | P34: {=INDEX($G$1:$G$100, MATCH(1, ($A$1:$A$100=P$25)*($B$1:$B$100=$K11), 0))} -> 18.844329 | Q34: {=INDEX($G$1:$G$100, MATCH(1, ($A$1:$A$100=Q$25)*($B$1:$B$100=$K11), 0))} -> #N/A | R34: {=INDEX($G$1:$G$100, MATCH(1, ($A$1:$A$100=R$25)*($B$1:$B$100=$K11), 0))} -> #N/A | S34: {=INDEX($G$1:$G$100, MATCH(1, ($A$1:$A$100=S$25)*($B$1:$B$100=$K11), 0))} -> 7.189667 | T34: =IF(ISNA(N11), TRUE, ABS($M11-N11) > MAX($P34, Q34)) -> TRUE | U34: =IF(ISNA(O11), TRUE, ABS($M11-O11) > MAX($P34, R34)) -> TRUE | V34: =IF(ISNA(P11), TRUE, ABS($M11-P11) > MAX($P34, S34)) -> FALSE | X34: =IF(ISNA(N11), TRUE, ABS($P11-N11) > MAX($S34, Q34)) -> TRUE | Y34: =IF(ISNA(O11), TRUE, ABS($P11-O11) > MAX($S34, R34)) -> TRUE | Z34: =IF(ISNA(M11), TRUE, ABS($P11-M11) > MAX($S34, P34)) -> FALSE | BB34: bom | BC34: collections | BD34: 5
